Workbook

Sheet Index
B2: PSI 시트 구성 | E2: 46057
B3: 구분 | C3: 내용 | D3: 비고 | E3: KPI_평가항목/성과지표 | G3: SCM 주 업무
B4: 대시보드 | C4: 재고지표, 상태별 현황 | D4: - | E4: - | G4: 주기 | H4: 목적 | I4: 비고
B5: PSI_메인 | C5: 월별 공급계획, 입출고, 재고 현황 | D5: - | E5: - | G5: 루틴 | H5: 재고관리 | I5: 데일리 현황 체크 및 필요시 정량발주
B6: ABC-XYZ분석 | C6: 구분에 따른 재고전략 | D6: - | E6: - | G6: 루틴 | H6: 납기관리 | I6: 발생시 마다 기재 관리
B7: 안전재고 | C7: 안전재고 산출 | D7: 26년_KPI_지표 | E7: 안전재고 준수율 | G7: 주별 | H7: 재고소진 독려 | I7: 대시보드 또는 재고분석 시트 이용
B8: 재고분석 | C8: 재고상태에 따른 조치 가이드 | D8: 26년_KPI_지표 | E8: 적정재고 달성률 | G8: 월별 | H8: 공급물량 산출 방식 | I8: 브랜드팀에 가이드 제시(S&OP)
B9: 공급물량 | C9: 월 공급물량 산출 | D9: - | E9: - | G9: 월별 | H9: 수요예측 및 SOP미팅 | I9: 예측 물량 도출(S&OP)
B10: 재고 | C10: 창고-본사 재고 데이터 | D10: 기존데이타 | E10: - | G10: 월별 | H10: 월 마감 | I10: 추세선 분석/리뷰 및 개선방안 도출
B11: 입항스케줄 | C11: 수입 관련 일정 및 현황 | D11: 기존데이타 | E11: - | G11: 분기 | H11: KPI 평가 및 지표 | I11: 기간별 평가
B12: 출고 (2) | C12: 년/월 출고 RAW 데이터 | D12: 기존데이타 | E12: -
B13: 통합지표 | C13: 월 마감 통합지표 | D13: - | E13: -
B14: 실출고율 | C14: 포캐스트 vs 실출고율 | D14: 26년_KPI_지표 | E14: 수요예측 vs 공급계획 | G14: 주요확인 및 업데이트 필요 사항
B15: 결품관리 | C15: 월별 결품률 관리 | D15: 26년_KPI_지표 | E15: 결품률 최소화 관리 | F15: 1 | G15: 현재고 : 재고현황 (향후 WMS 추출 양식으로 변경 필요)
B16: 회전율 관리 | C16: 회전율 및 회전일 관리 | D16: 26년_KPI_지표 | E16: 재고회전율 | F16: 2 | G16: 안전재고 : ABC 서비스 레벨 + XYZ보정계수 -> 상황에 맞게 비율(1.25 1.15 등) 적용(수정) 해야함
B17: 납기준수 관리 | C17: 수입/구매 납기율 관리 | D17: 26년_KPI_지표 | E17: 공급업체 납기준수율 | F17: 3 | G17: 적정재고 지표(재고분석) : 등급별 재고 대비 안전재고 비율(일출고량x리드타임+안전재고)
B18: 수요변동 관리 | C18: XYZ 등급 월별 관리 및 실행방안 | D18: - | E18: - | F18: 4 | G18: PSI_메인 : 월별 입출고/재고 물량 관리 데이터 -> 발생시 마다 업데이트
B20: 공급물량 산출
B21: 1. 기준정립 및 설정
B22: 1)리드타임 : 발주부터 입고완료까지의 기간 (가용재고시까지의 기간)
B23: 2)월평균 출고량 : 전년 동월 물량 + 올해 예상 증감 % 감안 + 계절성 감안(예, 겨울에는 여름제품 발주안함)
B24: 3)안전재고 : √LT(루트리드타임) x 수요표준편차 x 서비스레벨 -> "수요변동성"만 고려됨 , 향후 추가 리드타임 고려된 산출식으로 고도화 필요
B25: 4)ABC/XYZ 구분
B26: 5)안전재고 설정
B27: 6)재고 상태 설정
B28: 7)발주 여부 설정
B30: 2. 최종 공급 물량 산출
B31: (일평균출고 x 리드타임 x 사이클보정계수) + 안전재고
B33: 수요예측 (S&OP_미팅시 협의)
... B42: 납기기준 일정 vs 실 입고일

Sheet 대시보드
H1: 최근3개월 평균출고
B2: PSI 통합 대시보드 - 2026년 1월 기준
B4: 주요 재고 지표 | H4: 긴급 조치 필요 품목 TOP 10 | M4: 권장수량 | R4: 긴급조치 TOP10 선정 기준
B5: 지표 | C5: 값 | D5: 단위 | E5: 상태 | H5: 순위 | I5: SKU코드 | J5: 제품명 | K5: 상태 | L5: 현재고 | M5: 안전재고 | N5: 조치사항 | O5: 회전율 | P5: 비고 | R5: 1. 재고 상태 필터링
B6: 총 SKU 수 | C6: =COUNTA(재고분석!C2:C100) -> 99 | D6: 개 | E6: - | H6: 1 | I6: {=IFERROR(INDEX(재고분석!C:C,SMALL(IF((재고분석!N:N="부족")+(재고분석!N:N="재주문필요"),ROW(재고분석!N:N)),1)),"")} -> ABC13 | J6: =_xlfn.XLOOKUP(I6,PSI_메인!A:A,PSI_메인!B:B) -> 0 | K6: =_xlfn.XLOOKUP(I6,재고분석!C:C,재고분석!N:N) -> 부족 | L6: =SUMIF(재고분석!C:C,대시보드!I6,재고분석!H:H) -> 1 | M6: =SUMIF(재고분석!C:C,대시보드!I6,재고분석!I:I) -> 742 | N6: =IF(K6="부족","긴급발주",IF(K6="재주문필요","주문진행",IF(K6="","",IF(K6="과잉","프로모션",IF(K6="적정","정상",""))))) -> 긴급발주 | O6: =_xlfn.XLOOKUP(I6,재고분석!C:C,재고분석!O:O) -> 우수 | P6: =_xlfn.XLOOKUP(I6,'ABC-XYZ분석 (2)'!C:C,'ABC-XYZ분석 (2)'!B:B) -> 신재품 | R6: 긴급 조치가 필요한 상태: 오른쪽 캡쳐(표)참조
B7: 총 재고금액 | C7: =SUM(재고분석!R2:R100) -> 214333893 | D7: 원 | E7: - | H7: 2 | I7: {=IFERROR(INDEX(재고분석!C:C,SMALL(IF((재고분석!N:N="부족")+(재고분석!N:N="재주문필요"),ROW(재고분석!N:N)),2)),"")} -> ABC14 | J7: =_xlfn.XLOOKUP(I7,PSI_메인!A:A,PSI_메인!B:B) -> 0 | K7: =IFERROR(INDEX(재고분석!$N:$N,MATCH(I7,재고분석!$C:$C,0)),"") -> 부족 | L7: =SUMIF(재고분석!C:C,대시보드!I7,재고분석!H:H) -> 2 | M7: =SUMIF(재고분석!C:C,대시보드!I7,재고분석!I:I) -> 47 | N7: =IF(K7="부족","긴급발주",IF(K7="재주문필요","주문진행",IF(K7="","",IF(K7="과잉","프로모션",IF(K7="적정","정상",""))))) -> 긴급발주 | O7: =_xlfn.XLOOKUP(I7,재고분석!C:C,재고분석!O:O) -> 우수 | P7: =_xlfn.XLOOKUP(I7,'ABC-XYZ분석 (2)'!C:C,'ABC-XYZ분석 (2)'!B:B) -> 신재품 | R7: -부족 (현재고 < 안전재고) - 최우선
B8: 평균 재고회전일 | C8: =AVERAGE(재고분석!M:M) -> 280.19258 | D8: 일 | E8: - | H8: 3 | I8: {=IFERROR(INDEX(재고분석!C:C,SMALL(IF((재고분석!N:N="부족")+(재고분석!N:N="재주문필요"),ROW(재고분석!N:N)),3)),"")} -> ABC16 | J8: =_xlfn.XLOOKUP(I8,PSI_메인!A:A,PSI_메인!B:B) -> 0 | K8: =IFERROR(INDEX(재고분석!$N:$N,MATCH(I8,재고분석!$C:$C,0)),"") -> 부족 | L8: =SUMIF(재고분석!C:C,대시보드!I8,재고분석!H:H) -> 24 | M8: =SUMIF(재고분석!C:C,대시보드!I8,재고분석!I:I) -> 45 | N8: =IF(K8="부족","긴급발주",IF(K8="재주문필요","주문진행",IF(K8="","",IF(K8="과잉","프로모션",IF(K8="적정","정상",""))))) -> 긴급발주 | O8: =_xlfn.XLOOKUP(I8,재고분석!C:C,재고분석!O:O) -> 우수 | P8: =_xlfn.XLOOKUP(I8,'ABC-XYZ분석 (2)'!C:C,'ABC-XYZ분석 (2)'!B:B) -> 신재품 | R8: -재주문필요
B9: 재고부족 품목 | C9: =COUNTIF(재고분석!N:N,"부족") -> 27 | D9: 개 | E9: =IF(C9>0,"경고","정상") -> 경고 | H9: 4 | I9: {=IFERROR(INDEX(재고분석!C:C,SMALL(IF((재고분석!N:N="부족")+(재고분석!N:N="재주문필요"),ROW(재고분석!N:N)),4)),"")} -> ABC17 | J9: =_xlfn.XLOOKUP(I9,PSI_메인!A:A,PSI_메인!B:B) -> 0 | K9: =IFERROR(INDEX(재고분석!$N:$N,MATCH(I9,재고분석!$C:$C,0)),"") -> 부족 | L9: =SUMIF(재고분석!C:C,대시보드!I9,재고분석!H:H) -> 10 | M9: =SUMIF(재고분석!C:C,대시보드!I9,재고분석!I:I) -> 20 | N9: =IF(K9="부족","긴급발주",IF(K9="재주문필요","주문진행",IF(K9="","",IF(K9="과잉","프로모션",IF(K9="적정","정상",""))))) -> 긴급발주 | O9: =_xlfn.XLOOKUP(I9,재고분석!C:C,재고분석!O:O) -> 우수 | P9: =_xlfn.XLOOKUP(I9,'ABC-XYZ분석 (2)'!C:C,'ABC-XYZ분석 (2)'!B:B) -> 신재품 | R9: -과잉
B10: 재주문필요 품목 | C10: =COUNTIF(재고분석!N:N,"재주문") -> 8 | D10: 개 | E10: =IF(C10>0,"조치필요","정상") -> 조치필요 | H10: 5 | I10: {=IFERROR(INDEX(재고분석!C:C,SMALL(IF((재고분석!N:N="부족")+(재고분석!N:N="재주문필요"),ROW(재고분석!N:N)),5)),"")} -> ABC18 | J10: =_xlfn.XLOOKUP(I10,PSI_메인!A:A,PSI_메인!B:B) -> 0 | K10: =IFERROR(INDEX(재고분석!$N:$N,MATCH(I10,재고분석!$C:$C,0)),"") -> 부족 | L10: =SUMIF(재고분석!C:C,대시보드!I10,재고분석!H:H) -> 47 | M10: =SUMIF(재고분석!C:C,대시보드!I10,재고분석!I:I) -> 69 | N10: =IF(K10="부족","긴급발주",IF(K10="재주문필요","주문진행",IF(K10="","",IF(K10="과잉","프로모션",IF(K10="적정","정상",""))))) -> 긴급발주 | O10: =_xlfn.XLOOKUP(I10,재고분석!C:C,재고분석!O:O) -> 우수 | P10: =_xlfn.XLOOKUP(I10,'ABC-XYZ분석 (2)'!C:C,'ABC-XYZ분석 (2)'!B:B) -> 신재품
B11: 재고과잉 품목 | C11: =COUNTIF(재고분석!N:N,"과잉") -> 23 | D11: 개 | E11: =IF(C11>0,"검토필요","정상") -> 검토필요 | H11: 6 | I11: {=IFERROR(INDEX(재고분석!C:C,SMALL(IF((재고분석!N:N="부족")+(재고분석!N:N="재주문필요"),ROW(재고분석!N:N)),6)),"")} -> ABC19 | J11: =_xlfn.XLOOKUP(I11,PSI_메인!A:A,PSI_메인!B:B) -> 0 | K11: =IFERROR(INDEX(재고분석!$N:$N,MATCH(I11,재고분석!$C:$C,0)),"") -> 부족 | L11: =SUMIF(재고분석!C:C,대시보드!I11,재고분석!H:H) -> 15 | M11: =SUMIF(재고분석!C:C,대시보드!I11,재고분석!I:I) -> 24 | N11: =IF(K11="부족","긴급발주",IF(K11="재주문필요","주문진행",IF(K11="","",IF(K11="과잉","프로모션",IF(K11="적정","정상",""))))) -> 긴급발주 | O11: =_xlfn.XLOOKUP(I11,재고분석!C:C,재고분석!O:O) -> 우수 | P11: =_xlfn.XLOOKUP(I11,'ABC-XYZ분석 (2)'!C:C,'ABC-XYZ분석 (2)'!B:B) -> 신재품 | R11: 제외:
H12: 7 | I12: {=IFERROR(INDEX(재고분석!C:C,SMALL(IF((재고분석!N:N="부족")+(재고분석!N:N="재주문필요"),ROW(재고분석!N:N)),7)),"")} -> ABC20 | J12: =_xlfn.XLOOKUP(I12,PSI_메인!A:A,PSI_메인!B:B) -> 0 | K12: =IFERROR(INDEX(재고분석!$N:$N,MATCH(I12,재고분석!$C:$C,0)),"") -> 부족 | L12: =SUMIF(재고분석!C:C,대시보드!I12,재고분석!H:H) -> 3 | M12: =SUMIF(재고분석!C:C,대시보드!I12,재고분석!I:I) -> 48 | N12: =IF(K12="부족","긴급발주",IF(K12="재주문필요","주문진행",IF(K12="","",IF(K12="과잉","프로모션",IF(K12="적정","정상",""))))) -> 긴급발주 | O12: =_xlfn.XLOOKUP(I12,재고분석!C:C,재고분석!O:O) -> 우수 | P12: =_xlfn.XLOOKUP(I12,'ABC-XYZ분석 (2)'!C:C,'ABC-XYZ분석 (2)'!B:B) -> 신재품 | R12: 적정 오른쪽 캡쳐(표) 참조 -> 정상이므로 제외
B13: ABC-XYZ 재고 분포 (품목 수) | H13: 8 | I13: {=IFERROR(INDEX(재고분석!C:C,SMALL(IF((재고분석!N:N="부족")+(재고분석!N:N="재주문필요"),ROW(재고분석!N:N)),8)),"")} -> ABC21 | J13: =_xlfn.XLOOKUP(I13,PSI_메인!A:A,PSI_메인!B:B) -> 0 | K13: =IFERROR(INDEX(재고분석!$N:$N,MATCH(I13,재고분석!$C:$C,0)),"") -> 부족 | L13: =SUMIF(재고분석!C:C,대시보드!I13,재고분석!H:H) -> 6 | M13: =SUMIF(재고분석!C:C,대시보드!I13,재고분석!I:I) -> 47 | N13: =IF(K13="부족","긴급발주",IF(K13="재주문필요","주문진행",IF(K13="","",IF(K13="과잉","프로모션",IF(K13="적정","정상",""))))) -> 긴급발주 | O13: =_xlfn.XLOOKUP(I13,재고분석!C:C,재고분석!O:O) -> 우수 | P13: =_xlfn.XLOOKUP(I13,'ABC-XYZ분석 (2)'!C:C,'ABC-XYZ분석 (2)'!B:B) -> 신재품
B14: ABC-XYZ | C14: X (안정) | D14: Y (중간) | E14: Z (불안정) | F14: 합계 | H14: 9 | I14: {=IFERROR(INDEX(재고분석!C:C,SMALL(IF((재고분석!N:N="부족")+(재고분석!N:N="재주문필요"),ROW(재고분석!N:N)),9)),"")} -> ABC22 | J14: =_xlfn.XLOOKUP(I14,PSI_메인!A:A,PSI_메인!B:B) -> 0 | K14: =IFERROR(INDEX(재고분석!$N:$N,MATCH(I14,재고분석!$C:$C,0)),"") -> 부족 | L14: =SUMIF(재고분석!C:C,대시보드!I14,재고분석!H:H) -> 12 | M14: =SUMIF(재고분석!C:C,대시보드!I14,재고분석!I:I) -> 350 | N14: =IF(K14="부족","긴급발주",IF(K14="재주문필요","주문진행",IF(K14="","",IF(K14="과잉","프로모션",IF(K14="적정","정상",""))))) -> 긴급발주 | O14: =_xlfn.XLOOKUP(I14,재고분석!C:C,재고분석!O:O) -> 우수 | P14: =_xlfn.XLOOKUP(I14,'ABC-XYZ분석 (2)'!C:C,'ABC-XYZ분석 (2)'!B:B) -> 신재품 | R14: 2. 정렬 기준
B15: A (고가치) | C15: =COUNTIFS(재고분석!F:F,"A",재고분석!G:G,"X") -> 10 | D15: =COUNTIFS(재고분석!F:F,"A",재고분석!G:G,"Y") -> 16 | E15: =COUNTIFS(재고분석!F:F,"A",재고분석!G:G,"Z") -> 14 | F15: =SUM(C15:E15) -> 40 | H15: 10 | I15: {=IFERROR(INDEX(재고분석!C:C,SMALL(IF((재고분석!N:N="부족")+(재고분석!N:N="재주문필요"),ROW(재고분석!N:N)),10)),"")} -> ABC23 | J15: =_xlfn.XLOOKUP(I15,PSI_메인!A:A,PSI_메인!B:B) -> 0 | K15: =IFERROR(INDEX(재고분석!$N:$N,MATCH(I15,재고분석!$C:$C,0)),"") -> 부족 | L15: =SUMIF(재고분석!C:C,대시보드!I15,재고분석!H:H) -> 17 | M15: =SUMIF(재고분석!C:C,대시보드!I15,재고분석!I:I) -> 26 | N15: =IF(K15="부족","긴급발주",IF(K15="재주문필요","주문진행",IF(K15="","",IF(K15="과잉","프로모션",IF(K15="적정","정상",""))))) -> 긴급발주 | O15: =_xlfn.XLOOKUP(I15,재고분석!C:C,재고분석!O:O) -> 우수 | P15: =_xlfn.XLOOKUP(I15,'ABC-XYZ분석 (2)'!C:C,'ABC-XYZ분석 (2)'!B:B) -> 신재품 | R15: 심각도 순서:
B16: B (중가치) | C16: =COUNTIFS(재고분석!F:F,"B",재고분석!G:G,"X") -> 6 | D16: =COUNTIFS(재고분석!F:F,"B",재고분석!G:G,"Y") -> 16 | E16: =COUNTIFS(재고분석!F:F,"B",재고분석!G:G,"Z") -> 9 | F16: =SUM(C16:E16) -> 31 | H16: * 재고분석 시트에서 필터링하여 확인 | R16: 1순위: 부족 품목
B17: C (저가치) | C17: =COUNTIFS(재고분석!F:F,"C",재고분석!G:G,"X") -> 3 | D17: =COUNTIFS(재고분석!F:F,"C",재고분석!G:G,"Y") -> 12 | E17: =COUNTIFS(재고분석!F:F,"C",재고분석!G:G,"Z") -> 13 | F17: =SUM(C17:E17) -> 28 | R17: - 정렬: (안전재고 - 현재고) 차이 큰 순서
B18: 합계 | C18: =SUM(C15:C17) -> 19 | D18: =SUM(D15:D17) -> 44 | E18: =SUM(E15:E17) -> 36 | F18: =SUM(F15:F17) -> 99 | H18: 재고회전일 분석 | R18: - 또는: 현재고 ÷ 안전재고 비율이 낮은 순서
H19: 회전 느림 TOP 5 (개선 필요)
B20: 재고 상태별 현황 | I20: SKU | J20: 제품명 | K20: 최근3개월 월 평균출고량 | L20: 회전일 | R20: 2순위: 재주문필요 품목
B21: 재고상태 | C21: 품목수 | D21: 비율(%) | E21: 조치사항 | H21: 1 | I21: =IFERROR(INDEX(재고분석!$C:$C,MATCH(LARGE(재고분석!$M:$M,1),재고분석!$M:$M,0)),"") -> ABC2 | J21: =IFERROR(INDEX(재고분석!$D:$D,MATCH(I21,재고분석!$C:$C,0)),"") -> 0 | K21: =IFERROR(INDEX(재고분석!$J:$J,MATCH(I21,재고분석!$C:$C,0)),0) -> 6.3333333 | L21: =IFERROR(INDEX(재고분석!$M:$M,MATCH(I21,재고분석!$C:$C,0)),0) -> 8834.2105 | R21: - 정렬: 안전재고에 가까운 순서
B22: 적정 | C22: =COUNTIF(재고분석!N:N,B22) -> 3 | D22: =C22/$C$27*100 -> 3.030303 | E22: 현상유지 | H22: 2 | I22: =IFERROR(INDEX(재고분석!$C:$C,MATCH(LARGE(재고분석!$M:$M,2),재고분석!$M:$M,0)),"") -> ABC42 | J22: =IFERROR(INDEX(재고분석!$D:$D,MATCH(I22,재고분석!$C:$C,0)),"") -> 0 | K22: =IFERROR(INDEX(재고분석!$J:$J,MATCH(I22,재고분석!$C:$C,0)),0) -> 6.6666667 | L22: =IFERROR(INDEX(재고분석!$M:$M,MATCH(I22,재고분석!$C:$C,0)),0) -> 7393.5
B23: 재주문 | C23: =COUNTIF(재고분석!N:N,B23) -> 8 | D23: =C23/$C$27*100 -> 8.0808081 | E23: 발주진행 | H23: 3 | I23: =IFERROR(INDEX(재고분석!$C:$C,MATCH(LARGE(재고분석!$M:$M,3),재고분석!$M:$M,0)),"") -> ABC1 | J23: =IFERROR(INDEX(재고분석!$D:$D,MATCH(I23,재고분석!$C:$C,0)),"") -> 0 | K23: =IFERROR(INDEX(재고분석!$J:$J,MATCH(I23,재고분석!$C:$C,0)),0) -> 6 | L23: =IFERROR(INDEX(재고분석!$M:$M,MATCH(I23,재고분석!$C:$C,0)),0) -> 6165 | R23: 3순위: 과잉 품목
B24: 부족 | C24: =COUNTIF(재고분석!N:N,B24) -> 27 | D24: =C24/$C$27*100 -> 27.272727 | E24: 긴급발주 | H24: 4 | I24: =IFERROR(INDEX(재고분석!$C:$C,MATCH(LARGE(재고분석!$M:$M,4),재고분석!$M:$M,0)),"") -> ABC52 | J24: =IFERROR(INDEX(재고분석!$D:$D,MATCH(I24,재고분석!$C:$C,0)),"") -> 0 | K24: =IFERROR(INDEX(재고분석!$J:$J,MATCH(I24,재고분석!$C:$C,0)),0) -> 6 | L24: =IFERROR(INDEX(재고분석!$M:$M,MATCH(I24,재고분석!$C:$C,0)),0) -> 995 | R24: - 정렬: (현재고 - 안전재고×2) 차이 큰 순서
B25: 과잉 | C25: =COUNTIF(재고분석!N:N,B25) -> 23 | D25: =C25/$C$27*100 -> 23.232323 | E25: 프로모션검토 | H25: 5 | I25: =IFERROR(INDEX(재고분석!$C:$C,MATCH(LARGE(재고분석!$M:$M,5),재고분석!$M:$M,0)),"") -> ABC94 | J25: =IFERROR(INDEX(재고분석!$D:$D,MATCH(I25,재고분석!$C:$C,0)),"") -> 0 | K25: =IFERROR(INDEX(재고분석!$J:$J,MATCH(I25,재고분석!$C:$C,0)),0) -> 86.666667 | L25: =IFERROR(INDEX(재고분석!$M:$M,MATCH(I25,재고분석!$C:$C,0)),0) -> 916.96154
B26: 재고없음 | C26: =COUNTIF(재고분석!N:N,B26) -> 38 | D26: =C26/$C$27*100 -> 38.383838 | E26: 확인필요
B27: 합계 | C27: =SUM(C22:C26) -> 99 | D27: =SUM(D22:D26) -> 100 | E27: -
B29: -참조- | H29: 회전 빠름 TOP 5
B30: 1. 이 대시보드는 '재고분석' 시트 데이터를 기반으로 자동 계산 | I30: SKU | J30: 제품명 | K30: 최근3개월 월 평균출고량 | L30: 회전일
B31: 2. 재고부족/재주문필요 품목이 있으면 즉시 '발주전략' 시트를 확인 | H31: 1 | I31: {=IFERROR(INDEX(재고분석!$C:$C,MATCH(_xlfn.AGGREGATE(15,6,재고분석!$M:$M/(재고분석!$M:$M>0),1),재고분석!$M:$M,0)),"")} -> ABC79 | J31: =IFERROR(INDEX(재고분석!$D:$D,MATCH(I31,재고분석!$C:$C,0)),"") -> 0 | K31: =IFERROR(INDEX(재고분석!$J:$J,MATCH(I31,재고분석!$C:$C,0)),0) -> 716.33333 | L31: =IFERROR(INDEX(재고분석!$M:$M,MATCH(I31,재고분석!$C:$C,0)),0) -> 0.083759888
B32: 3. AX 등급(고가치+안정수요)은 충분한 재고를 유지필요 | H32: 2 | I32: {=IFERROR(INDEX(재고분석!$C:$C,MATCH(_xlfn.AGGREGATE(15,6,재고분석!$M:$M/(재고분석!$M:$M>0),2),재고분석!$M:$M,0)),"")} -> ABC14 | J32: =IFERROR(INDEX(재고분석!$D:$D,MATCH(I32,재고분석!$C:$C,0)),"") -> 0 | K32: =IFERROR(INDEX(재고분석!$J:$J,MATCH(I32,재고분석!$C:$C,0)),0) -> 557.66667 | L32: =IFERROR(INDEX(재고분석!$M:$M,MATCH(I32,재고분석!$C:$C,0)),0) -> 0.10759115
B33: 4. CZ 등급(저가치+불안정수요)은 주문 기반으로 운영 | H33: 3 | I33: {=IFERROR(INDEX(재고분석!$C:$C,MATCH(_xlfn.AGGREGATE(15,6,재고분석!$M:$M/(재고분석!$M:$M>0),3),재고분석!$M:$M,0)),"")} -> ABC20 | J33: =IFERROR(INDEX(재고분석!$D:$D,MATCH(I33,재고분석!$C:$C,0)),"") -> 0 | K33: =IFERROR(INDEX(재고분석!$J:$J,MATCH(I33,재고분석!$C:$C,0)),0) -> 279.33333 | L33: =IFERROR(INDEX(재고분석!$M:$M,MATCH(I33,재고분석!$C:$C,0)),0) -> 0.3221957
B34: 5. 재고회전일이 60일 이상이면 과잉재고로 판단하여 판촉 검토 필요 | H34: 4 | I34: {=IFERROR(INDEX(재고분석!$C:$C,MATCH(_xlfn.AGGREGATE(15,6,재고분석!$M:$M/(재고분석!$M:$M>0),4),재고분석!$M:$M,0)),"")} -> ABC81 | J34: =IFERROR(INDEX(재고분석!$D:$D,MATCH(I34,재고분석!$C:$C,0)),"") -> 0 | K34: =IFERROR(INDEX(재고분석!$J:$J,MATCH(I34,재고분석!$C:$C,0)),0) -> 82.333333 | L34: =IFERROR(INDEX(재고분석!$M:$M,MATCH(I34,재고분석!$C:$C,0)),0) -> 0.36437247
H35: 5 | I35: {=IFERROR(INDEX(재고분석!$C:$C,MATCH(_xlfn.AGGREGATE(15,6,재고분석!$M:$M/(재고분석!$M:$M>0),5),재고분석!$M:$M,0)),"")} -> ABC13 | J35: =IFERROR(INDEX(재고분석!$D:$D,MATCH(I35,재고분석!$C:$C,0)),"") -> 0 | K35: =IFERROR(INDEX(재고분석!$J:$J,MATCH(I35,재고분석!$C:$C,0)),0) -> 78.333333 | L35: =IFERROR(INDEX(재고분석!$M:$M,MATCH(I35,재고분석!$C:$C,0)),0) -> 0.38297872
H36: * 재고분석 시트를 회전일 기준으로 정렬하여 확인

Sheet PSI_메인
H1: 202512 | I1: 202601 | Q1: 202602 | Y1: 202603 | AG1: 202604 | AO1: 202605 | AW1: 202606 | BE1: 202607 | BM1: 202608 | BU1: 202609 | CC1: 202610 | CK1: 202611 | CS1: 202612
H2: 재고 | I2: 수요 | M2: 공급 | O2: 재고 | Q2: 수요 | U2: 공급 | W2: 재고 | Y2: 수요 | AC2: 공급 | AE2: 재고 | AG2: 수요 | AK2: 공급 | AM2: 재고 | AO2: 수요 | AS2: 공급 | AU2: 재고 | AW2: 수요 | BA2: 공급 | BC2: 재고 | BE2: 수요 | BI2: 공급 | BK2: 재고 | BM2: 수요 | BQ2: 공급 | BS2: 재고 | BU2: 수요 | BY2: 공급 | CA2: 재고 | CC2: 수요 | CG2: 공급 | CI2: 재고 | CK2: \ | CO2: 공급 | CQ2: 재고 | CS2: 수요 | CW2: 공급 | CY2: 재고
A3: SKU코드 | B3: 제품명 | C3: 카테고리 | D3: 계절 | E3: ABC 등급 | F3: XYZ 등급 | G3: 기초재고 | H3: 말재고실적 | I3: SCM F/C | J3: MD F/C | K3: S&OP | L3: 실판매 | M3: 입고계획 | N3: 입고실적 | O3: 말재고계획 | P3: 말재고실적 | Q3: SCM F/C | R3: MD F/C | S3: S&OP | T3: 실판매 | U3: 입고계획 | V3: 입고실적 | W3: 말재고계획 | X3: 말재고실적 | Y3: SCM F/C | Z3: MD F/C | AA3: S&OP | AB3: 실판매 | AC3: 입고계획 | AD3: 입고실적 | AE3: 말재고계획 | AF3: 말재고실적 | AG3: SCM F/C | AH3: MD F/C | AI3: S&OP | AJ3: 실판매 | AK3: 입고계획 | AL3: 입고실적 | AM3: 말재고계획 | AN3: 말재고실적 | AO3: SCM F/C | AP3: MD F/C | AQ3: S&OP | AR3: 실판매 | AS3: 입고계획 | AT3: 입고실적 | AU3: 말재고계획 | AV3: 말재고실적 | AW3: SCM F/C | AX3: MD F/C | AY3: S&OP | AZ3: 실판매 | BA3: 입고계획 | BB3: 입고실적 | BC3: 말재고계획 | BD3: 말재고실적 | BE3: SCM F/C | BF3: MD F/C | BG3: S&OP | BH3: 실판매 | BI3: 입고계획 | BJ3: 입고실적 | BK3: 말재고계획 | BL3: 말재고실적 | BM3: SCM F/C | BN3: MD F/C | BO3: S&OP | BP3: 실판매 | BQ3: 입고계획 | BR3: 입고실적 | BS3: 말재고계획 | BT3: 말재고실적 | BU3: SCM F/C | BV3: MD F/C | BW3: S&OP | BX3: 실판매 | BY3: 입고계획 | BZ3: 입고실적 | CA3: 말재고계획 | CB3: 말재고실적 | CC3: SCM F/C | CD3: MD F/C | CE3: S&OP | CF3: 실판매 | CG3: 입고계획 | CH3: 입고실적 | CI3: 말재고계획 | CJ3: 말재고실적 | CK3: SCM F/C | CL3: MD F/C | CM3: S&OP | CN3: 실판매 | CO3: 입고계획 | CP3: 입고실적 | CQ3: 말재고계획 | CR3: 말재고실적 | CS3: SCM F/C | CT3: MD F/C | CU3: S&OP | CV3: 실판매 | CW3: 입고계획 | CX3: 입고실적 | CY3: 말재고계획 | CZ3: 말재고실적
A4: ABC1 | D4: =_xlfn.XLOOKUP(A4,'ABC-XYZ분석 (2)'!C:C,'ABC-XYZ분석 (2)'!I:I) -> 여름 | E4: =_xlfn.XLOOKUP(A4,'ABC-XYZ분석 (2)'!C:C,'ABC-XYZ분석 (2)'!AC:AC) -> A | F4: =_xlfn.XLOOKUP(A4,'ABC-XYZ분석 (2)'!C:C,'ABC-XYZ분석 (2)'!AG:AG) -> Z | G4: =SUMIF(재고!C:C,PSI_메인!A4,재고!I:I) -> 1233 | H4: 1707 | I4: 0 | J4: 0 | K4: 0 | L4: 0 | M4: =SUMIFS(입항스케줄!J:J,입항스케줄!C:C,PSI_메인!A4,입항스케줄!U:U,"2601") -> 0 | N4: =SUMIFS(입항스케줄!J:J,입항스케줄!C:C,PSI_메인!A4,입항스케줄!V:V,"2601") -> 0 | O4: =H4+M4-K4 -> 1707 | P4: =H4+N4-L4 -> 1707 | Q4: 0 | R4: 0 | S4: 0 | T4: 0 | U4: =SUMIFS(입항스케줄!J:J,입항스케줄!C:C,PSI_메인!A4,입항스케줄!U:U,"2602") -> 0 | V4: =SUMIFS(입항스케줄!J:J,입항스케줄!C:C,PSI_메인!A4,입항스케줄!V:V,"2602") -> 0 | W4: =P4+U4-S4 -> 1707 | X4: =P4+V4-T4 -> 1707 | Y4: 0 | Z4: 0 | AA4: =ROUND((Y4+Z4)/2,0) -> 0 | AB4: 0 | AC4: =SUMIFS(입항스케줄!J:J,입항스케줄!C:C,PSI_메인!A4,입항스케줄!U:U,"2603") -> 0 | AD4: =SUMIFS(입항스케줄!J:J,입항스케줄!C:C,PSI_메인!A4,입항스케줄!V:V,"2603") -> 0 | AE4: =X4+AC4-AA4 -> 1707 | AF4: =X4+AD4-AB4 -> 1707 | AG4: 0 | AH4: 0 | AI4: =ROUND((AG4+AH4)/2,0) -> 0 | AJ4: 0 | AK4: =SUMIFS(입항스케줄!J:J,입항스케줄!C:C,PSI_메인!A4,입항스케줄!U:U,"2604") -> 0 | AL4: =SUMIFS(입항스케줄!J:J,입항스케줄!C:C,PSI_메인!A4,입항스케줄!V:V,"2604") -> 0 | AM4: =AF4+AK4-AI4 -> 1707 | AN4: =AF4+AL4-AJ4 -> 1707 | AO4: 0 | AP4: 0 | AQ4: =ROUND((AO4+AP4)/2,0) -> 0 | AR4: 0 | AU4: =AN4+AS4-AQ4 -> 1707 | AV4: =AN4+AT4-AR4 -> 1707 | AW4: 0 | AX4: 0 | AY4: =ROUND((AW4+AX4)/2,0) -> 0 | AZ4: 0 | BC4: =AV4+BA4-AY4 -> 1707 | BD4: =AV4+BB4-AZ4 -> 1707 | BE4: 0 | BF4: 0 | BG4: =ROUND((BE4+BF4)/2,0) -> 0 | BH4: 0 | BK4: =BD4+BI4-BG4 -> 1707 | BL4: =BD4+BJ4-BH4 -> 1707 | BM4: 0 | BN4: 0 | BO4: =ROUND((BM4+BN4)/2,0) -> 0 | BP4: 0 | BS4: =BL4+BQ4-BO4 -> 1707 | BT4: =BL4+BR4-BP4 -> 1707 | BU4: 0 | BV4: 0 | BW4: =ROUND((BU4+BV4)/2,0) -> 0 | BX4: 0 | CA4: =BT4+BY4-BW4 -> 1707 | CB4: =BT4+BZ4-BX4 -> 1707 | CC4: 0 | CD4: 0 | CE4: =ROUND((CC4+CD4)/2,0) -> 0 | CF4: 0 | CI4: =CB4+CG4-CE4 -> 1707 | CJ4: =CB4+CH4-CF4 -> 1707 | CK4: 0 | CL4: 0 | CM4: =ROUND((CK4+CL4)/2,0) -> 0 | CN4: 0 | CQ4: =CJ4+CO4-CM4 -> 1707 | CR4: =CJ4+CP4-CN4 -> 1707 | CS4: 0 | CT4: 0 | CU4: =ROUND((CS4+CT4)/2,0) -> 0 | CV4: 0 | CY4: =CR4+CW4-CU4 -> 1707 | CZ4: =CR4+CX4-CV4 -> 1707
A5: ABC2 | D5: =_xlfn.XLOOKUP(A5,'ABC-XYZ분석 (2)'!C:C,'ABC-XYZ분석 (2)'!I:I) -> 여름 | E5: =_xlfn.XLOOKUP(A5,'ABC-XYZ분석 (2)'!C:C,'ABC-XYZ분석 (2)'!AC:AC) -> A | F5: =_xlfn.XLOOKUP(A5,'ABC-XYZ분석 (2)'!C:C,'ABC-XYZ분석 (2)'!AG:AG) -> Z | G5: =SUMIF(재고!C:C,PSI_메인!A5,재고!I:I) -> 1865 | H5: 2987 | I5: 0 | J5: 0 | K5: 0 | L5: 0 | M5: =SUMIFS(입항스케줄!J:J,입항스케줄!C:C,PSI_메인!A5,입항스케줄!U:U,"2601") -> 0 | N5: =SUMIFS(입항스케줄!J:J,입항스케줄!C:C,PSI_메인!A5,입항스케줄!V:V,"2601") -> 0 | O5: =H5+M5-K5 -> 2987 | P5: =H5+N5-L5 -> 2987 | Q5: 0 | R5: 0 | S5: 0 | T5: 0 | U5: =SUMIFS(입항스케줄!J:J,입항스케줄!C:C,PSI_메인!A5,입항스케줄!U:U,"2602") -> 0 | V5: =SUMIFS(입항스케줄!J:J,입항스케줄!C:C,PSI_메인!A5,입항스케줄!V:V,"2602") -> 0 | W5: =P5+U5-S5 -> 2987 | X5: =P5+V5-T5 -> 2987 | Y5: 0 | Z5: 0 | AA5: =ROUND((Y5+Z5)/2,0) -> 0 | AB5: 0 | AC5: =SUMIFS(입항스케줄!J:J,입항스케줄!C:C,PSI_메인!A5,입항스케줄!U:U,"2603") -> 0 | AD5: =SUMIFS(입항스케줄!J:J,입항스케줄!C:C,PSI_메인!A5,입항스케줄!V:V,"2603") -> 0 | AE5: =X5+AC5-AA5 -> 2987 | AF5: =X5+AD5-AB5 -> 2987 | AG5: 0 | AH5: 0 | AI5: =ROUND((AG5+AH5)/2,0) -> 0 | AJ5: 0 | AK5: =SUMIFS(입항스케줄!J:J,입항스케줄!C:C,PSI_메인!A5,입항스케줄!U:U,"2604") -> 0 | AL5: =SUMIFS(입항스케줄!J:J,입항스케줄!C:C,PSI_메인!A5,입항스케줄!V:V,"2604") -> 0 | AM5: =AF5+AK5-AI5 -> 2987 | AN5: =AF5+AL5-AJ5 -> 2987 | AO5: 0 | AP5: 0 | AQ5: =ROUND((AO5+AP5)/2,0) -> 0 | AR5: 0 | AU5: =AN5+AS5-AQ5 -> 2987 | AV5: =AN5+AT5-AR5 -> 2987 | AW5: 0 | AX5: 0 | AY5: =ROUND((AW5+AX5)/2,0) -> 0 | AZ5: 0 | BC5: =AV5+BA5-AY5 -> 2987 | BD5: =AV5+BB5-AZ5 -> 2987 | BE5: 0 | BF5: 0 | BG5: =ROUND((BE5+BF5)/2,0) -> 0 | BH5: 0 | BK5: =BD5+BI5-BG5 -> 2987 | BL5: =BD5+BJ5-BH5 -> 2987 | BM5: 0 | BN5: 0 | BO5: =ROUND((BM5+BN5)/2,0) -> 0 | BP5: 0 | BS5: =BL5+BQ5-BO5 -> 2987 | BT5: =BL5+BR5-BP5 -> 2987 | BU5: 0 | BV5: 0 | BW5: =ROUND((BU5+BV5)/2,0) -> 0 | BX5: 0 | CA5: =BT5+BY5-BW5 -> 2987 | CB5: =BT5+BZ5-BX5 -> 2987 | CC5: 0 | CD5: 0 | CE5: =ROUND((CC5+CD5)/2,0) -> 0 | CF5: 0 | CI5: =CB5+CG5-CE5 -> 2987 | CJ5: =CB5+CH5-CF5 -> 2987 | CK5: 0 | CL5: 0 | CM5: =ROUND((CK5+CL5)/2,0) -> 0 | CN5: 0 | CQ5: =CJ5+CO5-CM5 -> 2987 | CR5: =CJ5+CP5-CN5 -> 2987 | CS5: 0 | CT5: 0 | CU5: =ROUND((CS5+CT5)/2,0) -> 0 | CV5: 0 | CY5: =CR5+CW5-CU5 -> 2987 | CZ5: =CR5+CX5-CV5 -> 2987
A6: ABC3 | D6: =_xlfn.XLOOKUP(A6,'ABC-XYZ분석 (2)'!C:C,'ABC-XYZ분석 (2)'!I:I) -> 여름 | E6: =_xlfn.XLOOKUP(A6,'ABC-XYZ분석 (2)'!C:C,'ABC-XYZ분석 (2)'!AC:AC) -> A | F6: =_xlfn.XLOOKUP(A6,'ABC-XYZ분석 (2)'!C:C,'ABC-XYZ분석 (2)'!AG:AG) -> Z | G6: =SUMIF(재고!C:C,PSI_메인!A6,재고!I:I) -> 0 | H6: 2425 | I6: 0 | J6: 0 | K6: 0 | L6: 0 | M6: =SUMIFS(입항스케줄!J:J,입항스케줄!C:C,PSI_메인!A6,입항스케줄!U:U,"2601") -> 0 | N6: =SUMIFS(입항스케줄!J:J,입항스케줄!C:C,PSI_메인!A6,입항스케줄!V:V,"2601") -> 0 | O6: =H6+M6-K6 -> 2425 | P6: =H6+N6-L6 -> 2425 | Q6: 0 | R6: 0 | S6: 0 | T6: 0 | U6: =SUMIFS(입항스케줄!J:J,입항스케줄!C:C,PSI_메인!A6,입항스케줄!U:U,"2602") -> 0 | V6: =SUMIFS(입항스케줄!J:J,입항스케줄!C:C,PSI_메인!A6,입항스케줄!V:V,"2602") -> 0 | W6: =P6+U6-S6 -> 2425 | X6: =P6+V6-T6 -> 2425 | Y6: 0 | Z6: 0 | AA6: =ROUND((Y6+Z6)/2,0) -> 0 | AB6: 0 | AC6: =SUMIFS(입항스케줄!J:J,입항스케줄!C:C,PSI_메인!A6,입항스케줄!U:U,"2603") -> 0 | AD6: =SUMIFS(입항스케줄!J:J,입항스케줄!C:C,PSI_메인!A6,입항스케줄!V:V,"2603") -> 0 | AE6: =X6+AC6-AA6 -> 2425 | AF6: =X6+AD6-AB6 -> 2425 | AG6: 0 | AH6: 0 | AI6: =ROUND((AG6+AH6)/2,0) -> 0 | AJ6: 0 | AK6: =SUMIFS(입항스케줄!J:J,입항스케줄!C:C,PSI_메인!A6,입항스케줄!U:U,"2604") -> 0 | AL6: =SUMIFS(입항스케줄!J:J,입항스케줄!C:C,PSI_메인!A6,입항스케줄!V:V,"2604") -> 0 | AM6: =AF6+AK6-AI6 -> 2425 | AN6: =AF6+AL6-AJ6 -> 2425 | AO6: 0 | AP6: 0 | AQ6: =ROUND((AO6+AP6)/2,0) -> 0 | AR6: 0 | AU6: =AN6+AS6-AQ6 -> 2425 | AV6: =AN6+AT6-AR6 -> 2425 | AW6: 0 | AX6: 0 | AY6: =ROUND((AW6+AX6)/2,0) -> 0 | AZ6: 0 | BC6: =AV6+BA6-AY6 -> 2425 | BD6: =AV6+BB6-AZ6 -> 2425 | BE6: 0 | BF6: 0 | BG6: =ROUND((BE6+BF6)/2,0) -> 0 | BH6: 0 | BK6: =BD6+BI6-BG6 -> 2425 | BL6: =BD6+BJ6-BH6 -> 2425 | BM6: 0 | BN6: 0 | BO6: =ROUND((BM6+BN6)/2,0) -> 0 | BP6: 0 | BS6: =BL6+BQ6-BO6 -> 2425 | BT6: =BL6+BR6-BP6 -> 2425 | BU6: 0 | BV6: 0 | BW6: =ROUND((BU6+BV6)/2,0) -> 0 | BX6: 0 | CA6: =BT6+BY6-BW6 -> 2425 | CB6: =BT6+BZ6-BX6 -> 2425 | CC6: 0 | CD6: 0 | CE6: =ROUND((CC6+CD6)/2,0) -> 0 | CF6: 0 | CI6: =CB6+CG6-CE6 -> 2425 | CJ6: =CB6+CH6-CF6 -> 2425 | CK6: 0 | CL6: 0 | CM6: =ROUND((CK6+CL6)/2,0) -> 0 | CN6: 0 | CQ6: =CJ6+CO6-CM6 -> 2425 | CR6: =CJ6+CP6-CN6 -> 2425 | CS6: 0 | CT6: 0 | CU6: =ROUND((CS6+CT6)/2,0) -> 0 | CV6: 0 | CY6: =CR6+CW6-CU6 -> 2425 | CZ6: =CR6+CX6-CV6 -> 2425
A7: ABC4 | D7: =_xlfn.XLOOKUP(A7,'ABC-XYZ분석 (2)'!C:C,'ABC-XYZ분석 (2)'!I:I) -> 여름 | E7: =_xlfn.XLOOKUP(A7,'ABC-XYZ분석 (2)'!C:C,'ABC-XYZ분석 (2)'!AC:AC) -> A | F7: =_xlfn.XLOOKUP(A7,'ABC-XYZ분석 (2)'!C:C,'ABC-XYZ분석 (2)'!AG:AG) -> Z | G7: =SUMIF(재고!C:C,PSI_메인!A7,재고!I:I) -> 0 | H7: 3187 | I7: 0 | J7: 0 | K7: 530 | L7: 0 | M7: =SUMIFS(입항스케줄!J:J,입항스케줄!C:C,PSI_메인!A7,입항스케줄!U:U,"2601") -> 0 | N7: =SUMIFS(입항스케줄!J:J,입항스케줄!C:C,PSI_메인!A7,입항스케줄!V:V,"2601") -> 0 | O7: =H7+M7-K7 -> 2657 | P7: =H7+N7-L7 -> 3187 | Q7: 0 | R7: 0 | S7: 600 | T7: 0 | U7: =SUMIFS(입항스케줄!J:J,입항스케줄!C:C,PSI_메인!A7,입항스케줄!U:U,"2602") -> 0 | V7: =SUMIFS(입항스케줄!J:J,입항스케줄!C:C,PSI_메인!A7,입항스케줄!V:V,"2602") -> 0 | W7: =P7+U7-S7 -> 2587 | X7: =P7+V7-T7 -> 3187 | Y7: 0 | Z7: 0 | AA7: =ROUND((Y7+Z7)/2,0) -> 0 | AB7: 0 | AC7: =SUMIFS(입항스케줄!J:J,입항스케줄!C:C,PSI_메인!A7,입항스케줄!U:U,"2603") -> 0 | AD7: =SUMIFS(입항스케줄!J:J,입항스케줄!C:C,PSI_메인!A7,입항스케줄!V:V,"2603") -> 0 | AE7: =X7+AC7-AA7 -> 3187 | AF7: =X7+AD7-AB7 -> 3187 | AG7: 0 | AH7: 0 | AI7: =ROUND((AG7+AH7)/2,0) -> 0 | AJ7: 0 | AK7: =SUMIFS(입항스케줄!J:J,입항스케줄!C:C,PSI_메인!A7,입항스케줄!U:U,"2604") -> 0 | AL7: =SUMIFS(입항스케줄!J:J,입항스케줄!C:C,PSI_메인!A7,입항스케줄!V:V,"2604") -> 0 | AM7: =AF7+AK7-AI7 -> 3187 | AN7: =AF7+AL7-AJ7 -> 3187 | AO7: 0 | AP7: 0 | AQ7: =ROUND((AO7+AP7)/2,0) -> 0 | AR7: 0 | AU7: =AN7+AS7-AQ7 -> 3187 | AV7: =AN7+AT7-AR7 -> 3187 | AW7: 0 | AX7: 0 | AY7: =ROUND((AW7+AX7)/2,0) -> 0 | AZ7: 0 | BC7: =AV7+BA7-AY7 -> 3187 | BD7: =AV7+BB7-AZ7 -> 3187 | BE7: 0 | BF7: 0 | BG7: =ROUND((BE7+BF7)/2,0) -> 0 | BH7: 0 | BK7: =BD7+BI7-BG7 -> 3187 | BL7: =BD7+BJ7-BH7 -> 3187 | BM7: 0 | BN7: 0 | BO7: =ROUND((BM7+BN7)/2,0) -> 0 | BP7: 0 | BS7: =BL7+BQ7-BO7 -> 3187 | BT7: =BL7+BR7-BP7 -> 3187 | BU7: 0 | BV7: 0 | BW7: =ROUND((BU7+BV7)/2,0) -> 0 | BX7: 0 | CA7: =BT7+BY7-BW7 -> 3187 | CB7: =BT7+BZ7-BX7 -> 3187 | CC7: 0 | CD7: 0 | CE7: =ROUND((CC7+CD7)/2,0) -> 0 | CF7: 0 | CI7: =CB7+CG7-CE7 -> 3187 | CJ7: =CB7+CH7-CF7 -> 3187 | CK7: 0 | CL7: 0 | CM7: =ROUND((CK7+CL7)/2,0) -> 0 | CN7: 0 | CQ7: =CJ7+CO7-CM7 -> 3187 | CR7: =CJ7+CP7-CN7 -> 3187 | CS7: 0 | CT7: 0 | CU7: =ROUND((CS7+CT7)/2,0) -> 0 | CV7: 0 | CY7: =CR7+CW7-CU7 -> 3187 | CZ7: =CR7+CX7-CV7 -> 3187
A8: ABC5 | D8: =_xlfn.XLOOKUP(A8,'ABC-XYZ분석 (2)'!C:C,'ABC-XYZ분석 (2)'!I:I) -> 여름 | E8: =_xlfn.XLOOKUP(A8,'ABC-XYZ분석 (2)'!C:C,'ABC-XYZ분석 (2)'!AC:AC) -> A | F8: =_xlfn.XLOOKUP(A8,'ABC-XYZ분석 (2)'!C:C,'ABC-XYZ분석 (2)'!AG:AG) -> Z | G8: =SUMIF(재고!C:C,PSI_메인!A8,재고!I:I) -> 0 | H8: 3022 | I8: 0 | J8: 0 | K8: 125 | L8: 0 | M8: =SUMIFS(입항스케줄!J:J,입항스케줄!C:C,PSI_메인!A8,입항스케줄!U:U,"2601") -> 0 | N8: =SUMIFS(입항스케줄!J:J,입항스케줄!C:C,PSI_메인!A8,입항스케줄!V:V,"2601") -> 0 | O8: =H8+M8-K8 -> 2897 | P8: =H8+N8-L8 -> 3022 | Q8: 0 | R8: 0 | S8: 100 | T8: 0 | U8: =SUMIFS(입항스케줄!J:J,입항스케줄!C:C,PSI_메인!A8,입항스케줄!U:U,"2602") -> 0 | V8: =SUMIFS(입항스케줄!J:J,입항스케줄!C:C,PSI_메인!A8,입항스케줄!V:V,"2602") -> 0 | W8: =P8+U8-S8 -> 2922 | X8: =P8+V8-T8 -> 3022 | Y8: 0 | Z8: 0 | AA8: =ROUND((Y8+Z8)/2,0) -> 0 | AB8: 0 | AC8: =SUMIFS(입항스케줄!J:J,입항스케줄!C:C,PSI_메인!A8,입항스케줄!U:U,"2603") -> 0 | AD8: =SUMIFS(입항스케줄!J:J,입항스케줄!C:C,PSI_메인!A8,입항스케줄!V:V,"2603") -> 0 | AE8: =X8+AC8-AA8 -> 3022 | AF8: =X8+AD8-AB8 -> 3022 | AG8: 0 | AH8: 0 | AI8: =ROUND((AG8+AH8)/2,0) -> 0 | AJ8: 0 | AK8: =SUMIFS(입항스케줄!J:J,입항스케줄!C:C,PSI_메인!A8,입항스케줄!U:U,"2604") -> 0 | AL8: =SUMIFS(입항스케줄!J:J,입항스케줄!C:C,PSI_메인!A8,입항스케줄!V:V,"2604") -> 0 | AM8: =AF8+AK8-AI8 -> 3022 | AN8: =AF8+AL8-AJ8 -> 3022 | AO8: 0 | AP8: 0 | AQ8: =ROUND((AO8+AP8)/2,0) -> 0 | AR8: 0 | AU8: =AN8+AS8-AQ8 -> 3022 | AV8: =AN8+AT8-AR8 -> 3022 | AW8: 0 | AX8: 0 | AY8: =ROUND((AW8+AX8)/2,0) -> 0 | AZ8: 0 | BC8: =AV8+BA8-AY8 -> 3022 | BD8: =AV8+BB8-AZ8 -> 3022 | BE8: 0 | BF8: 0 | BG8: =ROUND((BE8+BF8)/2,0) -> 0 | BH8: 0 | BK8: =BD8+BI8-BG8 -> 3022 | BL8: =BD8+BJ8-BH8 -> 3022 | BM8: 0 | BN8: 0 | BO8: =ROUND((BM8+BN8)/2,0) -> 0 | BP8: 0 | BS8: =BL8+BQ8-BO8 -> 3022 | BT8: =BL8+BR8-BP8 -> 3022 | BU8: 0 | BV8: 0 | BW8: =ROUND((BU8+BV8)/2,0) -> 0 | BX8: 0 | CA8: =BT8+BY8-BW8 -> 3022 | CB8: =BT8+BZ8-BX8 -> 3022 | CC8: 0 | CD8: 0 | CE8: =ROUND((CC8+CD8)/2,0) -> 0 | CF8: 0 | CI8: =CB8+CG8-CE8 -> 3022 | CJ8: =CB8+CH8-CF8 -> 3022 | CK8: 0 | CL8: 0 | CM8: =ROUND((CK8+CL8)/2,0) -> 0 | CN8: 0 | CQ8: =CJ8+CO8-CM8 -> 3022 | CR8: =CJ8+CP8-CN8 -> 3022 | CS8: 0 | CT8: 0 | CU8: =ROUND((CS8+CT8)/2,0) -> 0 | CV8: 0 | CY8: =CR8+CW8-CU8 -> 3022 | CZ8: =CR8+CX8-CV8 -> 3022
A9: ABC6 | D9: =_xlfn.XLOOKUP(A9,'ABC-XYZ분석 (2)'!C:C,'ABC-XYZ분석 (2)'!I:I) -> 여름 | E9: =_xlfn.XLOOKUP(A9,'ABC-XYZ분석 (2)'!C:C,'ABC-XYZ분석 (2)'!AC:AC) -> A | F9: =_xlfn.XLOOKUP(A9,'ABC-XYZ분석 (2)'!C:C,'ABC-XYZ분석 (2)'!AG:AG) -> Z | G9: =SUMIF(재고!C:C,PSI_메인!A9,재고!I:I) -> 0 | H9: 13414 | I9: 0 | J9: 0 | K9: 0 | L9: 0 | M9: =SUMIFS(입항스케줄!J:J,입항스케줄!C:C,PSI_메인!A9,입항스케줄!U:U,"2601") -> 0 | N9: =SUMIFS(입항스케줄!J:J,입항스케줄!C:C,PSI_메인!A9,입항스케줄!V:V,"2601") -> 0 | O9: =$G9+M9-K9 -> 0 | P9: =$G9+N9-L9 -> 0 | Q9: 0 | R9: 0 | S9: 0 | T9: 0 | U9: =SUMIFS(입항스케줄!J:J,입항스케줄!C:C,PSI_메인!A9,입항스케줄!U:U,"2602") -> 0 | V9: =SUMIFS(입항스케줄!J:J,입항스케줄!C:C,PSI_메인!A9,입항스케줄!V:V,"2602") -> 0 | W9: =$G9+U9-S9 -> 0 | X9: =$G9+V9-T9 -> 0 | Y9: 0 | Z9: 0 | AA9: =ROUND((Y9+Z9)/2,0) -> 0 | AB9: 0 | AC9: =SUMIFS(입항스케줄!J:J,입항스케줄!C:C,PSI_메인!A9,입항스케줄!U:U,"2603") -> 0 | AD9: =SUMIFS(입항스케줄!J:J,입항스케줄!C:C,PSI_메인!A9,입항스케줄!V:V,"2603") -> 0 | AE9: =$G9+AC9-AA9 -> 0 | AF9: =$G9+AD9-AB9 -> 0 | AG9: 0 | AH9: 0 | AI9: =ROUND((AG9+AH9)/2,0) -> 0 | AJ9: 0 | AK9: =SUMIFS(입항스케줄!J:J,입항스케줄!C:C,PSI_메인!A9,입항스케줄!U:U,"2604") -> 0 | AL9: =SUMIFS(입항스케줄!J:J,입항스케줄!C:C,PSI_메인!A9,입항스케줄!V:V,"2604") -> 0 | AM9: =$G9+AK9-AI9 -> 0 | AN9: =$G9+AL9-AJ9 -> 0 | AO9: 0 | AP9: 0 | AQ9: =ROUND((AO9+AP9)/2,0) -> 0 | AR9: 0 | AU9: =$G9+AS9-AQ9 -> 0 | AV9: =$G9+AT9-AR9 -> 0 | AW9: 0 | AX9: 0 | AY9: =ROUND((AW9+AX9)/2,0) -> 0 | AZ9: 0 | BC9: =$G9+BA9-AY9 -> 0 | BD9: =$G9+BB9-AZ9 -> 0 | BE9: 0 | BF9: 0 | BG9: =ROUND((BE9+BF9)/2,0) -> 0 | BH9: 0 | BK9: =$G9+BI9-BG9 -> 0 | BL9: =$G9+BJ9-BH9 -> 0 | BM9: 0 | BN9: 0 | BO9: =ROUND((BM9+BN9)/2,0) -> 0 | BP9: 0 | BS9: =$G9+BQ9-BO9 -> 0 | BT9: =$G9+BR9-BP9 -> 0 | BU9: 0 | BV9: 0 | BW9: =ROUND((BU9+BV9)/2,0) -> 0 | BX9: 0 | CA9: =$G9+BY9-BW9 -> 0 | CB9: =$G9+BZ9-BX9 -> 0 | CC9: 0 | CD9: 0 | CE9: =ROUND((CC9+CD9)/2,0) -> 0 | CF9: 0 | CI9: =$G9+CG9-CE9 -> 0 | CJ9: =$G9+CH9-CF9 -> 0 | CK9: 0 | CL9: 0 | CM9: =ROUND((CK9+CL9)/2,0) -> 0 | CN9: 0 | CQ9: =$G9+CO9-CM9 -> 0 | CR9: =$G9+CP9-CN9 -> 0 | CS9: 0 | CT9: 0 | CU9: =ROUND((CS9+CT9)/2,0) -> 0 | CV9: 0 | CY9: =$G9+CW9-CU9 -> 0 | CZ9: =$G9+CX9-CV9 -> 0
A10: ABC7 | D10: =_xlfn.XLOOKUP(A10,'ABC-XYZ분석 (2)'!C:C,'ABC-XYZ분석 (2)'!I:I) -> 여름 | E10: =_xlfn.XLOOKUP(A10,'ABC-XYZ분석 (2)'!C:C,'ABC-XYZ분석 (2)'!AC:AC) -> A | F10: =_xlfn.XLOOKUP(A10,'ABC-XYZ분석 (2)'!C:C,'ABC-XYZ분석 (2)'!AG:AG) -> Z | G10: =SUMIF(재고!C:C,PSI_메인!A10,재고!I:I) -> 0 | H10: 7601 | I10: 0 | J10: 0 | K10: 0 | L10: 0 | M10: =SUMIFS(입항스케줄!J:J,입항스케줄!C:C,PSI_메인!A10,입항스케줄!U:U,"2601") -> 0 | N10: =SUMIFS(입항스케줄!J:J,입항스케줄!C:C,PSI_메인!A10,입항스케줄!V:V,"2601") -> 0 | O10: =$G10+M10-K10 -> 0 | P10: =$G10+N10-L10 -> 0 | Q10: 0 | R10: 0 | S10: 0 | T10: 0 | U10: =SUMIFS(입항스케줄!J:J,입항스케줄!C:C,PSI_메인!A10,입항스케줄!U:U,"2602") -> 0 | V10: =SUMIFS(입항스케줄!J:J,입항스케줄!C:C,PSI_메인!A10,입항스케줄!V:V,"2602") -> 0 | W10: =$G10+U10-S10 -> 0 | X10: =$G10+V10-T10 -> 0 | Y10: 0 | Z10: 0 | AA10: =ROUND((Y10+Z10)/2,0) -> 0 | AB10: 0 | AC10: =SUMIFS(입항스케줄!J:J,입항스케줄!C:C,PSI_메인!A10,입항스케줄!U:U,"2603") -> 0 | AD10: =SUMIFS(입항스케줄!J:J,입항스케줄!C:C,PSI_메인!A10,입항스케줄!V:V,"2603") -> 0 | AE10: =$G10+AC10-AA10 -> 0 | AF10: =$G10+AD10-AB10 -> 0 | AG10: 0 | AH10: 0 | AI10: =ROUND((AG10+AH10)/2,0) -> 0 | AJ10: 0 | AK10: =SUMIFS(입항스케줄!J:J,입항스케줄!C:C,PSI_메인!A10,입항스케줄!U:U,"2604") -> 0 | AL10: =SUMIFS(입항스케줄!J:J,입항스케줄!C:C,PSI_메인!A10,입항스케줄!V:V,"2604") -> 0 | AM10: =$G10+AK10-AI10 -> 0 | AN10: =$G10+AL10-AJ10 -> 0 | AO10: 0 | AP10: 0 | AQ10: =ROUND((AO10+AP10)/2,0) -> 0 | AR10: 0 | AU10: =$G10+AS10-AQ10 -> 0 | AV10: =$G10+AT10-AR10 -> 0 | AW10: 0 | AX10: 0 | AY10: =ROUND((AW10+AX10)/2,0) -> 0 | AZ10: 0 | BC10: =$G10+BA10-AY10 -> 0 | BD10: =$G10+BB10-AZ10 -> 0 | BE10: 0 | BF10: 0 | BG10: =ROUND((BE10+BF10)/2,0) -> 0 | BH10: 0 | BK10: =$G10+BI10-BG10 -> 0 | BL10: =$G10+BJ10-BH10 -> 0 | BM10: 0 | BN10: 0 | BO10: =ROUND((BM10+BN10)/2,0) -> 0 | BP10: 0 | BS10: =$G10+BQ10-BO10 -> 0 | BT10: =$G10+BR10-BP10 -> 0 | BU10: 0 | BV10: 0 | BW10: =ROUND((BU10+BV10)/2,0) -> 0 | BX10: 0 | CA10: =$G10+BY10-BW10 -> 0 | CB10: =$G10+BZ10-BX10 -> 0 | CC10: 0 | CD10: 0 | CE10: =ROUND((CC10+CD10)/2,0) -> 0 | CF10: 0 | CI10: =$G10+CG10-CE10 -> 0 | CJ10: =$G10+CH10-CF10 -> 0 | CK10: 0 | CL10: 0 | CM10: =ROUND((CK10+CL10)/2,0) -> 0 | CN10: 0 | CQ10: =$G10+CO10-CM10 -> 0 | CR10: =$G10+CP10-CN10 -> 0 | CS10: 0 | CT10: 0 | CU10: =ROUND((CS10+CT10)/2,0) -> 0 | CV10: 0 | CY10: =$G10+CW10-CU10 -> 0 | CZ10: =$G10+CX10-CV10 -> 0
A11: ABC8 | D11: =_xlfn.XLOOKUP(A11,'ABC-XYZ분석 (2)'!C:C,'ABC-XYZ분석 (2)'!I:I) -> 사계절 | E11: =_xlfn.XLOOKUP(A11,'ABC-XYZ분석 (2)'!C:C,'ABC-XYZ분석 (2)'!AC:AC) -> A | F11: =_xlfn.XLOOKUP(A11,'ABC-XYZ분석 (2)'!C:C,'ABC-XYZ분석 (2)'!AG:AG) -> X | G11: =SUMIF(재고!C:C,PSI_메인!A11,재고!I:I) -> 0 | H11: 3274 | I11: 0 | J11: 0 | K11: 0 | L11: 0 | M11: =SUMIFS(입항스케줄!J:J,입항스케줄!C:C,PSI_메인!A11,입항스케줄!U:U,"2601") -> 0 | N11: =SUMIFS(입항스케줄!J:J,입항스케줄!C:C,PSI_메인!A11,입항스케줄!V:V,"2601") -> 0 | O11: =$G11+M11-K11 -> 0 | P11: =$G11+N11-L11 -> 0 | Q11: 0 | R11: 0 | S11: 0 | T11: 0 | U11: =SUMIFS(입항스케줄!J:J,입항스케줄!C:C,PSI_메인!A11,입항스케줄!U:U,"2602") -> 0 | V11: =SUMIFS(입항스케줄!J:J,입항스케줄!C:C,PSI_메인!A11,입항스케줄!V:V,"2602") -> 0 | W11: =$G11+U11-S11 -> 0 | X11: =$G11+V11-T11 -> 0 | Y11: 0 | Z11: 0 | AA11: =ROUND((Y11+Z11)/2,0) -> 0 | AB11: 0 | AC11: =SUMIFS(입항스케줄!J:J,입항스케줄!C:C,PSI_메인!A11,입항스케줄!U:U,"2603") -> 0 | AD11: =SUMIFS(입항스케줄!J:J,입항스케줄!C:C,PSI_메인!A11,입항스케줄!V:V,"2603") -> 0 | AE11: =$G11+AC11-AA11 -> 0 | AF11: =$G11+AD11-AB11 -> 0 | AG11: 0 | AH11: 0 | AI11: =ROUND((AG11+AH11)/2,0) -> 0 | AJ11: 0 | AK11: =SUMIFS(입항스케줄!J:J,입항스케줄!C:C,PSI_메인!A11,입항스케줄!U:U,"2604") -> 0 | AL11: =SUMIFS(입항스케줄!J:J,입항스케줄!C:C,PSI_메인!A11,입항스케줄!V:V,"2604") -> 0 | AM11: =$G11+AK11-AI11 -> 0 | AN11: =$G11+AL11-AJ11 -> 0 | AO11: 0 | AP11: 0 | AQ11: =ROUND((AO11+AP11)/2,0) -> 0 | AR11: 0 | AU11: =$G11+AS11-AQ11 -> 0 | AV11: =$G11+AT11-AR11 -> 0 | AW11: 0 | AX11: 0 | AY11: =ROUND((AW11+AX11)/2,0) -> 0 | AZ11: 0 | BC11: =$G11+BA11-AY11 -> 0 | BD11: =$G11+BB11-AZ11 -> 0 | BE11: 0 | BF11: 0 | BG11: =ROUND((BE11+BF11)/2,0) -> 0 | BH11: 0 | BK11: =$G11+BI11-BG11 -> 0 | BL11: =$G11+BJ11-BH11 -> 0 | BM11: 0 | BN11: 0 | BO11: =ROUND((BM11+BN11)/2,0) -> 0 | BP11: 0 | BS11: =$G11+BQ11-BO11 -> 0 | BT11: =$G11+BR11-BP11 -> 0 | BU11: 0 | BV11: 0 | BW11: =ROUND((BU11+BV11)/2,0) -> 0 | BX11: 0 | CA11: =$G11+BY11-BW11 -> 0 | CB11: =$G11+BZ11-BX11 -> 0 | CC11: 0 | CD11: 0 | CE11: =ROUND((CC11+CD11)/2,0) -> 0 | CF11: 0 | CI11: =$G11+CG11-CE11 -> 0 | CJ11: =$G11+CH11-CF11 -> 0 | CK11: 0 | CL11: 0 | CM11: =ROUND((CK11+CL11)/2,0) -> 0 | CN11: 0 | CQ11: =$G11+CO11-CM11 -> 0 | CR11: =$G11+CP11-CN11 -> 0 | CS11: 0 | CT11: 0 | CU11: =ROUND((CS11+CT11)/2,0) -> 0 | CV11: 0 | CY11: =$G11+CW11-CU11 -> 0 | CZ11: =$G11+CX11-CV11 -> 0
A12: ABC9 | D12: =_xlfn.XLOOKUP(A12,'ABC-XYZ분석 (2)'!C:C,'ABC-XYZ분석 (2)'!I:I) -> 여름 | E12: =_xlfn.XLOOKUP(A12,'ABC-XYZ분석 (2)'!C:C,'ABC-XYZ분석 (2)'!AC:AC) -> A | F12: =_xlfn.XLOOKUP(A12,'ABC-XYZ분석 (2)'!C:C,'ABC-XYZ분석 (2)'!AG:AG) -> Z | G12: =SUMIF(재고!C:C,PSI_메인!A12,재고!I:I) -> 0 | H12: 6767 | I12: 0 | J12: 0 | K12: 0 | L12: 0 | M12: =SUMIFS(입항스케줄!J:J,입항스케줄!C:C,PSI_메인!A12,입항스케줄!U:U,"2601") -> 0 | N12: =SUMIFS(입항스케줄!J:J,입항스케줄!C:C,PSI_메인!A12,입항스케줄!V:V,"2601") -> 0 | O12: =$G12+M12-K12 -> 0 | P12: =$G12+N12-L12 -> 0 | Q12: 0 | R12: 0 | S12: 0 | T12: 0 | U12: =SUMIFS(입항스케줄!J:J,입항스케줄!C:C,PSI_메인!A12,입항스케줄!U:U,"2602") -> 0 | V12: =SUMIFS(입항스케줄!J:J,입항스케줄!C:C,PSI_메인!A12,입항스케줄!V:V,"2602") -> 0 | W12: =$G12+U12-S12 -> 0 | X12: =$G12+V12-T12 -> 0 | Y12: 0 | Z12: 0 | AA12: =ROUND((Y12+Z12)/2,0) -> 0 | AB12: 0 | AC12: =SUMIFS(입항스케줄!J:J,입항스케줄!C:C,PSI_메인!A12,입항스케줄!U:U,"2603") -> 0 | AD12: =SUMIFS(입항스케줄!J:J,입항스케줄!C:C,PSI_메인!A12,입항스케줄!V:V,"2603") -> 0 | AE12: =$G12+AC12-AA12 -> 0 | AF12: =$G12+AD12-AB12 -> 0 | AG12: 0 | AH12: 0 | AI12: =ROUND((AG12+AH12)/2,0) -> 0 | AJ12: 0 | AK12: =SUMIFS(입항스케줄!J:J,입항스케줄!C:C,PSI_메인!A12,입항스케줄!U:U,"2604") -> 0 | AL12: =SUMIFS(입항스케줄!J:J,입항스케줄!C:C,PSI_메인!A12,입항스케줄!V:V,"2604") -> 0 | AM12: =$G12+AK12-AI12 -> 0 | AN12: =$G12+AL12-AJ12 -> 0 | AO12: 0 | AP12: 0 | AQ12: =ROUND((AO12+AP12)/2,0) -> 0 | AR12: 0 | AU12: =$G12+AS12-AQ12 -> 0 | AV12: =$G12+AT12-AR12 -> 0 | AW12: 0 | AX12: 0 | AY12: =ROUND((AW12+AX12)/2,0) -> 0 | AZ12: 0 | BC12: =$G12+BA12-AY12 -> 0 | BD12: =$G12+BB12-AZ12 -> 0 | BE12: 0 | BF12: 0 | BG12: =ROUND((BE12+BF12)/2,0) -> 0 | BH12: 0 | BK12: =$G12+BI12-BG12 -> 0 | BL12: =$G12+BJ12-BH12 -> 0 | BM12: 0 | BN12: 0 | BO12: =ROUND((BM12+BN12)/2,0) -> 0 | BP12: 0 | BS12: =$G12+BQ12-BO12 -> 0 | BT12: =$G12+BR12-BP12 -> 0 | BU12: 0 | BV12: 0 | BW12: =ROUND((BU12+BV12)/2,0) -> 0 | BX12: 0 | CA12: =$G12+BY12-BW12 -> 0 | CB12: =$G12+BZ12-BX12 -> 0 | CC12: 0 | CD12: 0 | CE12: =ROUND((CC12+CD12)/2,0) -> 0 | CF12: 0 | CI12: =$G12+CG12-CE12 -> 0 | CJ12: =$G12+CH12-CF12 -> 0 | CK12: 0 | CL12: 0 | CM12: =ROUND((CK12+CL12)/2,0) -> 0 | CN12: 0 | CQ12: =$G12+CO12-CM12 -> 0 | CR12: =$G12+CP12-CN12 -> 0 | CS12: 0 | CT12: 0 | CU12: =ROUND((CS12+CT12)/2,0) -> 0 | CV12: 0 | CY12: =$G12+CW12-CU12 -> 0 | CZ12: =$G12+CX12-CV12 -> 0
A13: ABC10 | D13: =_xlfn.XLOOKUP(A13,'ABC-XYZ분석 (2)'!C:C,'ABC-XYZ분석 (2)'!I:I) -> 사계절 | E13: =_xlfn.XLOOKUP(A13,'ABC-XYZ분석 (2)'!C:C,'ABC-XYZ분석 (2)'!AC:AC) -> A | F13: =_xlfn.XLOOKUP(A13,'ABC-XYZ분석 (2)'!C:C,'ABC-XYZ분석 (2)'!AG:AG) -> X | G13: =SUMIF(재고!C:C,PSI_메인!A13,재고!I:I) -> 0 | H13: 10244 | I13: 0 | J13: 0 | K13: 0 | L13: 0 | M13: =SUMIFS(입항스케줄!J:J,입항스케줄!C:C,PSI_메인!A13,입항스케줄!U:U,"2601") -> 0 | N13: =SUMIFS(입항스케줄!J:J,입항스케줄!C:C,PSI_메인!A13,입항스케줄!V:V,"2601") -> 0 | O13: =$G13+M13-K13 -> 0 | P13: =$G13+N13-L13 -> 0 | Q13: 0 | R13: 0 | S13: 0 | T13: 0 | U13: =SUMIFS(입항스케줄!J:J,입항스케줄!C:C,PSI_메인!A13,입항스케줄!U:U,"2602") -> 0 | V13: =SUMIFS(입항스케줄!J:J,입항스케줄!C:C,PSI_메인!A13,입항스케줄!V:V,"2602") -> 0 | W13: =$G13+U13-S13 -> 0 | X13: =$G13+V13-T13 -> 0 | Y13: 0 | Z13: 0 | AA13: =ROUND((Y13+Z13)/2,0) -> 0 | AB13: 0 | AC13: =SUMIFS(입항스케줄!J:J,입항스케줄!C:C,PSI_메인!A13,입항스케줄!U:U,"2603") -> 0 | AD13: =SUMIFS(입항스케줄!J:J,입항스케줄!C:C,PSI_메인!A13,입항스케줄!V:V,"2603") -> 0 | AE13: =$G13+AC13-AA13 -> 0 | AF13: =$G13+AD13-AB13 -> 0 | AG13: 0 | AH13: 0 | AI13: =ROUND((AG13+AH13)/2,0) -> 0 | AJ13: 0 | AK13: =SUMIFS(입항스케줄!J:J,입항스케줄!C:C,PSI_메인!A13,입항스케줄!U:U,"2604") -> 0 | AL13: =SUMIFS(입항스케줄!J:J,입항스케줄!C:C,PSI_메인!A13,입항스케줄!V:V,"2604") -> 0 | AM13: =$G13+AK13-AI13 -> 0 | AN13: =$G13+AL13-AJ13 -> 0 | AO13: 0 | AP13: 0 | AQ13: =ROUND((AO13+AP13)/2,0) -> 0 | AR13: 0 | AU13: =$G13+AS13-AQ13 -> 0 | AV13: =$G13+AT13-AR13 -> 0 | AW13: 0 | AX13: 0 | AY13: =ROUND((AW13+AX13)/2,0) -> 0 | AZ13: 0 | BC13: =$G13+BA13-AY13 -> 0 | BD13: =$G13+BB13-AZ13 -> 0 | BE13: 0 | BF13: 0 | BG13: =ROUND((BE13+BF13)/2,0) -> 0 | BH13: 0 | BK13: =$G13+BI13-BG13 -> 0 | BL13: =$G13+BJ13-BH13 -> 0 | BM13: 0 | BN13: 0 | BO13: =ROUND((BM13+BN13)/2,0) -> 0 | BP13: 0 | BS13: =$G13+BQ13-BO13 -> 0 | BT13: =$G13+BR13-BP13 -> 0 | BU13: 0 | BV13: 0 | BW13: =ROUND((BU13+BV13)/2,0) -> 0 | BX13: 0 | CA13: =$G13+BY13-BW13 -> 0 | CB13: =$G13+BZ13-BX13 -> 0 | CC13: 0 | CD13: 0 | CE13: =ROUND((CC13+CD13)/2,0) -> 0 | CF13: 0 | CI13: =$G13+CG13-CE13 -> 0 | CJ13: =$G13+CH13-CF13 -> 0 | CK13: 0 | CL13: 0 | CM13: =ROUND((CK13+CL13)/2,0) -> 0 | CN13: 0 | CQ13: =$G13+CO13-CM13 -> 0 | CR13: =$G13+CP13-CN13 -> 0 | CS13: 0 | CT13: 0 | CU13: =ROUND((CS13+CT13)/2,0) -> 0 | CV13: 0 | CY13: =$G13+CW13-CU13 -> 0 | CZ13: =$G13+CX13-CV13 -> 0
A14: ABC11 | D14: =_xlfn.XLOOKUP(A14,'ABC-XYZ분석 (2)'!C:C,'ABC-XYZ분석 (2)'!I:I) -> 사계절 | E14: =_xlfn.XLOOKUP(A14,'ABC-XYZ분석 (2)'!C:C,'ABC-XYZ분석 (2)'!AC:AC) -> A | F14: =_xlfn.XLOOKUP(A14,'ABC-XYZ분석 (2)'!C:C,'ABC-XYZ분석 (2)'!AG:AG) -> X | G14: =SUMIF(재고!C:C,PSI_메인!A14,재고!I:I) -> 0 | H14: 2877 | I14: 0 | J14: 0 | K14: 400 | L14: 0 | M14: =SUMIFS(입항스케줄!J:J,입항스케줄!C:C,PSI_메인!A14,입항스케줄!U:U,"2601") -> 0 | N14: =SUMIFS(입항스케줄!J:J,입항스케줄!C:C,PSI_메인!A14,입항스케줄!V:V,"2601") -> 0 | O14: =$G14+M14-K14 -> -400 | P14: =$G14+N14-L14 -> 0 | Q14: 0 | R14: 0 | S14: 500 | T14: 0 | U14: =SUMIFS(입항스케줄!J:J,입항스케줄!C:C,PSI_메인!A14,입항스케줄!U:U,"2602") -> 0 | V14: =SUMIFS(입항스케줄!J:J,입항스케줄!C:C,PSI_메인!A14,입항스케줄!V:V,"2602") -> 0 | W14: =$G14+U14-S14 -> -500 | X14: =$G14+V14-T14 -> 0 | Y14: 0 | Z14: 0 | AA14: =ROUND((Y14+Z14)/2,0) -> 0 | AB14: 0 | AC14: =SUMIFS(입항스케줄!J:J,입항스케줄!C:C,PSI_메인!A14,입항스케줄!U:U,"2603") -> 0 | AD14: =SUMIFS(입항스케줄!J:J,입항스케줄!C:C,PSI_메인!A14,입항스케줄!V:V,"2603") -> 0 | AE14: =$G14+AC14-AA14 -> 0 | AF14: =$G14+AD14-AB14 -> 0 | AG14: 0 | AH14: 0 | AI14: =ROUND((AG14+AH14)/2,0) -> 0 | AJ14: 0 | AK14: =SUMIFS(입항스케줄!J:J,입항스케줄!C:C,PSI_메인!A14,입항스케줄!U:U,"2604") -> 0 | AL14: =SUMIFS(입항스케줄!J:J,입항스케줄!C:C,PSI_메인!A14,입항스케줄!V:V,"2604") -> 0 | AM14: =$G14+AK14-AI14 -> 0 | AN14: =$G14+AL14-AJ14 -> 0 | AO14: 0 | AP14: 0 | AQ14: =ROUND((AO14+AP14)/2,0) -> 0 | AR14: 0 | AU14: =$G14+AS14-AQ14 -> 0 | AV14: =$G14+AT14-AR14 -> 0 | AW14: 0 | AX14: 0 | AY14: =ROUND((AW14+AX14)/2,0) -> 0 | AZ14: 0 | BC14: =$G14+BA14-AY14 -> 0 | BD14: =$G14+BB14-AZ14 -> 0 | BE14: 0 | BF14: 0 | BG14: =ROUND((BE14+BF14)/2,0) -> 0 | BH14: 0 | BK14: =$G14+BI14-BG14 -> 0 | BL14: =$G14+BJ14-BH14 -> 0 | BM14: 0 | BN14: 0 | BO14: =ROUND((BM14+BN14)/2,0) -> 0 | BP14: 0 | BS14: =$G14+BQ14-BO14 -> 0 | BT14: =$G14+BR14-BP14 -> 0 | BU14: 0 | BV14: 0 | BW14: =ROUND((BU14+BV14)/2,0) -> 0 | BX14: 0 | CA14: =$G14+BY14-BW14 -> 0 | CB14: =$G14+BZ14-BX14 -> 0 | CC14: 0 | CD14: 0 | CE14: =ROUND((CC14+CD14)/2,0) -> 0 | CF14: 0 | CI14: =$G14+CG14-CE14 -> 0 | CJ14: =$G14+CH14-CF14 -> 0 | CK14: 0 | CL14: 0 | CM14: =ROUND((CK14+CL14)/2,0) -> 0 | CN14: 0 | CQ14: =$G14+CO14-CM14 -> 0 | CR14: =$G14+CP14-CN14 -> 0 | CS14: 0 | CT14: 0 | CU14: =ROUND((CS14+CT14)/2,0) -> 0 | CV14: 0 | CY14: =$G14+CW14-CU14 -> 0 | CZ14: =$G14+CX14-CV14 -> 0
A15: ABC12 | D15: =_xlfn.XLOOKUP(A15,'ABC-XYZ분석 (2)'!C:C,'ABC-XYZ분석 (2)'!I:I) -> 사계절 | E15: =_xlfn.XLOOKUP(A15,'ABC-XYZ분석 (2)'!C:C,'ABC-XYZ분석 (2)'!AC:AC) -> A | F15: =_xlfn.XLOOKUP(A15,'ABC-XYZ분석 (2)'!C:C,'ABC-XYZ분석 (2)'!AG:AG) -> X | G15: =SUMIF(재고!C:C,PSI_메인!A15,재고!I:I) -> 2800 | H15: 3641 | I15: 0 | J15: 0 | K15: 2000 | L15: 0 | M15: =SUMIFS(입항스케줄!J:J,입항스케줄!C:C,PSI_메인!A15,입항스케줄!U:U,"2601") -> 0 | N15: =SUMIFS(입항스케줄!J:J,입항스케줄!C:C,PSI_메인!A15,입항스케줄!V:V,"2601") -> 0 | O15: =$G15+M15-K15 -> 800 | P15: =$G15+N15-L15 -> 2800 | Q15: 0 | R15: 0 | S15: 2000 | T15: 0 | U15: =SUMIFS(입항스케줄!J:J,입항스케줄!C:C,PSI_메인!A15,입항스케줄!U:U,"2602") -> 0 | V15: =SUMIFS(입항스케줄!J:J,입항스케줄!C:C,PSI_메인!A15,입항스케줄!V:V,"2602") -> 0 | W15: =$G15+U15-S15 -> 800 | X15: =$G15+V15-T15 -> 2800 | Y15: 0 | Z15: 0 | AA15: =ROUND((Y15+Z15)/2,0) -> 0 | AB15: 0 | AC15: =SUMIFS(입항스케줄!J:J,입항스케줄!C:C,PSI_메인!A15,입항스케줄!U:U,"2603") -> 0 | AD15: =SUMIFS(입항스케줄!J:J,입항스케줄!C:C,PSI_메인!A15,입항스케줄!V:V,"2603") -> 0 | AE15: =$G15+AC15-AA15 -> 2800 | AF15: =$G15+AD15-AB15 -> 2800 | AG15: 0 | AH15: 0 | AI15: =ROUND((AG15+AH15)/2,0) -> 0 | AJ15: 0 | AK15: =SUMIFS(입항스케줄!J:J,입항스케줄!C:C,PSI_메인!A15,입항스케줄!U:U,"2604") -> 0 | AL15: =SUMIFS(입항스케줄!J:J,입항스케줄!C:C,PSI_메인!A15,입항스케줄!V:V,"2604") -> 0 | AM15: =$G15+AK15-AI15 -> 2800 | AN15: =$G15+AL15-AJ15 -> 2800 | AO15: 0 | AP15: 0 | AQ15: =ROUND((AO15+AP15)/2,0) -> 0 | AR15: 0 | AU15: =$G15+AS15-AQ15 -> 2800 | AV15: =$G15+AT15-AR15 -> 2800 | AW15: 0 | AX15: 0 | AY15: =ROUND((AW15+AX15)/2,0) -> 0 | AZ15: 0 | BC15: =$G15+BA15-AY15 -> 2800 | BD15: =$G15+BB15-AZ15 -> 2800 | BE15: 0 | BF15: 0 | BG15: =ROUND((BE15+BF15)/2,0) -> 0 | BH15: 0 | BK15: =$G15+BI15-BG15 -> 2800 | BL15: =$G15+BJ15-BH15 -> 2800 | BM15: 0 | BN15: 0 | BO15: =ROUND((BM15+BN15)/2,0) -> 0 | BP15: 0 | BS15: =$G15+BQ15-BO15 -> 2800 | BT15: =$G15+BR15-BP15 -> 2800 | BU15: 0 | BV15: 0 | BW15: =ROUND((BU15+BV15)/2,0) -> 0 | BX15: 0 | CA15: =$G15+BY15-BW15 -> 2800 | CB15: =$G15+BZ15-BX15 -> 2800 | CC15: 0 | CD15: 0 | CE15: =ROUND((CC15+CD15)/2,0) -> 0 | CF15: 0 | CI15: =$G15+CG15-CE15 -> 2800 | CJ15: =$G15+CH15-CF15 -> 2800 | CK15: 0 | CL15: 0 | CM15: =ROUND((CK15+CL15)/2,0) -> 0 | CN15: 0 | CQ15: =$G15+CO15-CM15 -> 2800 | CR15: =$G15+CP15-CN15 -> 2800 | CS15: 0 | CT15: 0 | CU15: =ROUND((CS15+CT15)/2,0) -> 0 | CV15: 0 | CY15: =$G15+CW15-CU15 -> 2800 | CZ15: =$G15+CX15-CV15 -> 2800
A16: ABC13 | D16: =_xlfn.XLOOKUP(A16,'ABC-XYZ분석 (2)'!C:C,'ABC-XYZ분석 (2)'!I:I) -> 여름 | E16: =_xlfn.XLOOKUP(A16,'ABC-XYZ분석 (2)'!C:C,'ABC-XYZ분석 (2)'!AC:AC) -> A | F16: =_xlfn.XLOOKUP(A16,'ABC-XYZ분석 (2)'!C:C,'ABC-XYZ분석 (2)'!AG:AG) -> Z | G16: =SUMIF(재고!C:C,PSI_메인!A16,재고!I:I) -> 1 | H16: 837 | I16: 0 | J16: 0 | K16: 487.5 | L16: 0 | M16: =SUMIFS(입항스케줄!J:J,입항스케줄!C:C,PSI_메인!A16,입항스케줄!U:U,"2601") -> 0 | N16: =SUMIFS(입항스케줄!J:J,입항스케줄!C:C,PSI_메인!A16,입항스케줄!V:V,"2601") -> 0 | O16: =$G16+M16-K16 -> -486.5 | P16: =$G16+N16-L16 -> 1 | Q16: 0 | R16: 0 | S16: 300 | T16: 0 | U16: =SUMIFS(입항스케줄!J:J,입항스케줄!C:C,PSI_메인!A16,입항스케줄!U:U,"2602") -> 0 | V16: =SUMIFS(입항스케줄!J:J,입항스케줄!C:C,PSI_메인!A16,입항스케줄!V:V,"2602") -> 0 | W16: =$G16+U16-S16 -> -299 | X16: =$G16+V16-T16 -> 1 | Y16: 0 | Z16: 0 | AA16: =ROUND((Y16+Z16)/2,0) -> 0 | AB16: 0 | AC16: =SUMIFS(입항스케줄!J:J,입항스케줄!C:C,PSI_메인!A16,입항스케줄!U:U,"2603") -> 0 | AD16: =SUMIFS(입항스케줄!J:J,입항스케줄!C:C,PSI_메인!A16,입항스케줄!V:V,"2603") -> 0 | AE16: =$G16+AC16-AA16 -> 1 | AF16: =$G16+AD16-AB16 -> 1 | AG16: 0 | AH16: 0 | AI16: =ROUND((AG16+AH16)/2,0) -> 0 | AJ16: 0 | AK16: =SUMIFS(입항스케줄!J:J,입항스케줄!C:C,PSI_메인!A16,입항스케줄!U:U,"2604") -> 0 | AL16: =SUMIFS(입항스케줄!J:J,입항스케줄!C:C,PSI_메인!A16,입항스케줄!V:V,"2604") -> 0 | AM16: =$G16+AK16-AI16 -> 1 | AN16: =$G16+AL16-AJ16 -> 1 | AO16: 0 | AP16: 0 | AQ16: =ROUND((AO16+AP16)/2,0) -> 0 | AR16: 0 | AU16: =$G16+AS16-AQ16 -> 1 | AV16: =$G16+AT16-AR16 -> 1 | AW16: 0 | AX16: 0 | AY16: =ROUND((AW16+AX16)/2,0) -> 0 | AZ16: 0 | BC16: =$G16+BA16-AY16 -> 1 | BD16: =$G16+BB16-AZ16 -> 1 | BE16: 0 | BF16: 0 | BG16: =ROUND((BE16+BF16)/2,0) -> 0 | BH16: 0 | BK16: =$G16+BI16-BG16 -> 1 | BL16: =$G16+BJ16-BH16 -> 1 | BM16: 0 | BN16: 0 | BO16: =ROUND((BM16+BN16)/2,0) -> 0 | BP16: 0 | BS16: =$G16+BQ16-BO16 -> 1 | BT16: =$G16+BR16-BP16 -> 1 | BU16: 0 | BV16: 0 | BW16: =ROUND((BU16+BV16)/2,0) -> 0 | BX16: 0 | CA16: =$G16+BY16-BW16 -> 1 | CB16: =$G16+BZ16-BX16 -> 1 | CC16: 0 | CD16: 0 | CE16: =ROUND((CC16+CD16)/2,0) -> 0 | CF16: 0 | CI16: =$G16+CG16-CE16 -> 1 | CJ16: =$G16+CH16-CF16 -> 1 | CK16: 0 | CL16: 0 | CM16: =ROUND((CK16+CL16)/2,0) -> 0 | CN16: 0 | CQ16: =$G16+CO16-CM16 -> 1 | CR16: =$G16+CP16-CN16 -> 1 | CS16: 0 | CT16: 0 | CU16: =ROUND((CS16+CT16)/2,0) -> 0 | CV16: 0 | CY16: =$G16+CW16-CU16 -> 1 | CZ16: =$G16+CX16-CV16 -> 1
A17: ABC14 | D17: =_xlfn.XLOOKUP(A17,'ABC-XYZ분석 (2)'!C:C,'ABC-XYZ분석 (2)'!I:I) -> 사계절 | E17: =_xlfn.XLOOKUP(A17,'ABC-XYZ분석 (2)'!C:C,'ABC-XYZ분석 (2)'!AC:AC) -> A | F17: =_xlfn.XLOOKUP(A17,'ABC-XYZ분석 (2)'!C:C,'ABC-XYZ분석 (2)'!AG:AG) -> Y | G17: =SUMIF(재고!C:C,PSI_메인!A17,재고!I:I) -> 2 | H17: 9201 | I17: 0 | J17: 0 | K17: 0 | L17: 0 | M17: =SUMIFS(입항스케줄!J:J,입항스케줄!C:C,PSI_메인!A17,입항스케줄!U:U,"2601") -> 0 | N17: =SUMIFS(입항스케줄!J:J,입항스케줄!C:C,PSI_메인!A17,입항스케줄!V:V,"2601") -> 0 | O17: =$G17+M17-K17 -> 2 | P17: =$G17+N17-L17 -> 2 | Q17: 0 | R17: 0 | S17: 0 | T17: 0 | U17: =SUMIFS(입항스케줄!J:J,입항스케줄!C:C,PSI_메인!A17,입항스케줄!U:U,"2602") -> 0 | V17: =SUMIFS(입항스케줄!J:J,입항스케줄!C:C,PSI_메인!A17,입항스케줄!V:V,"2602") -> 0 | W17: =$G17+U17-S17 -> 2 | X17: =$G17+V17-T17 -> 2 | Y17: 0 | Z17: 0 | AA17: =ROUND((Y17+Z17)/2,0) -> 0 | AB17: 0 | AC17: =SUMIFS(입항스케줄!J:J,입항스케줄!C:C,PSI_메인!A17,입항스케줄!U:U,"2603") -> 0 | AD17: =SUMIFS(입항스케줄!J:J,입항스케줄!C:C,PSI_메인!A17,입항스케줄!V:V,"2603") -> 0 | AE17: =$G17+AC17-AA17 -> 2 | AF17: =$G17+AD17-AB17 -> 2 | AG17: 0 | AH17: 0 | AI17: =ROUND((AG17+AH17)/2,0) -> 0 | AJ17: 0 | AK17: =SUMIFS(입항스케줄!J:J,입항스케줄!C:C,PSI_메인!A17,입항스케줄!U:U,"2604") -> 0 | AL17: =SUMIFS(입항스케줄!J:J,입항스케줄!C:C,PSI_메인!A17,입항스케줄!V:V,"2604") -> 0 | AM17: =$G17+AK17-AI17 -> 2 | AN17: =$G17+AL17-AJ17 -> 2 | AO17: 0 | AP17: 0 | AQ17: =ROUND((AO17+AP17)/2,0) -> 0 | AR17: 0 | AU17: =$G17+AS17-AQ17 -> 2 | AV17: =$G17+AT17-AR17 -> 2 | AW17: 0 | AX17: 0 | AY17: =ROUND((AW17+AX17)/2,0) -> 0 | AZ17: 0 | BC17: =$G17+BA17-AY17 -> 2 | BD17: =$G17+BB17-AZ17 -> 2 | BE17: 0 | BF17: 0 | BG17: =ROUND((BE17+BF17)/2,0) -> 0 | BH17: 0 | BK17: =$G17+BI17-BG17 -> 2 | BL17: =$G17+BJ17-BH17 -> 2 | BM17: 0 | BN17: 0 | BO17: =ROUND((BM17+BN17)/2,0) -> 0 | BP17: 0 | BS17: =$G17+BQ17-BO17 -> 2 | BT17: =$G17+BR17-BP17 -> 2 | BU17: 0 | BV17: 0 | BW17: =ROUND((BU17+BV17)/2,0) -> 0 | BX17: 0 | CA17: =$G17+BY17-BW17 -> 2 | CB17: =$G17+BZ17-BX17 -> 2 | CC17: 0 | CD17: 0 | CE17: =ROUND((CC17+CD17)/2,0) -> 0 | CF17: 0 | CI17: =$G17+CG17-CE17 -> 2 | CJ17: =$G17+CH17-CF17 -> 2 | CK17: 0 | CL17: 0 | CM17: =ROUND((CK17+CL17)/2,0) -> 0 | CN17: 0 | CQ17: =$G17+CO17-CM17 -> 2 | CR17: =$G17+CP17-CN17 -> 2 | CS17: 0 | CT17: 0 | CU17: =ROUND((CS17+CT17)/2,0) -> 0 | CV17: 0 | CY17: =$G17+CW17-CU17 -> 2 | CZ17: =$G17+CX17-CV17 -> 2
A18: ABC15 | D18: =_xlfn.XLOOKUP(A18,'ABC-XYZ분석 (2)'!C:C,'ABC-XYZ분석 (2)'!I:I) -> 여름 | E18: =_xlfn.XLOOKUP(A18,'ABC-XYZ분석 (2)'!C:C,'ABC-XYZ분석 (2)'!AC:AC) -> A | F18: =_xlfn.XLOOKUP(A18,'ABC-XYZ분석 (2)'!C:C,'ABC-XYZ분석 (2)'!AG:AG) -> Z | G18: =SUMIF(재고!C:C,PSI_메인!A18,재고!I:I) -> 0 | H18: 556 | I18: 0 | J18: 0 | K18: 300 | L18: 0 | M18: =SUMIFS(입항스케줄!J:J,입항스케줄!C:C,PSI_메인!A18,입항스케줄!U:U,"2601") -> 0 | N18: =SUMIFS(입항스케줄!J:J,입항스케줄!C:C,PSI_메인!A18,입항스케줄!V:V,"2601") -> 0 | O18: =$G18+M18-K18 -> -300 | P18: =$G18+N18-L18 -> 0 | Q18: 0 | R18: 0 | S18: 300 | T18: 0 | U18: =SUMIFS(입항스케줄!J:J,입항스케줄!C:C,PSI_메인!A18,입항스케줄!U:U,"2602") -> 0 | V18: =SUMIFS(입항스케줄!J:J,입항스케줄!C:C,PSI_메인!A18,입항스케줄!V:V,"2602") -> 0 | W18: =$G18+U18-S18 -> -300 | X18: =$G18+V18-T18 -> 0 | Y18: 0 | Z18: 0 | AA18: =ROUND((Y18+Z18)/2,0) -> 0 | AB18: 0 | AC18: =SUMIFS(입항스케줄!J:J,입항스케줄!C:C,PSI_메인!A18,입항스케줄!U:U,"2603") -> 0 | AD18: =SUMIFS(입항스케줄!J:J,입항스케줄!C:C,PSI_메인!A18,입항스케줄!V:V,"2603") -> 0 | AE18: =$G18+AC18-AA18 -> 0 | AF18: =$G18+AD18-AB18 -> 0 | AG18: 0 | AH18: 0 | AI18: =ROUND((AG18+AH18)/2,0) -> 0 | AJ18: 0 | AK18: =SUMIFS(입항스케줄!J:J,입항스케줄!C:C,PSI_메인!A18,입항스케줄!U:U,"2604") -> 0 | AL18: =SUMIFS(입항스케줄!J:J,입항스케줄!C:C,PSI_메인!A18,입항스케줄!V:V,"2604") -> 0 | AM18: =$G18+AK18-AI18 -> 0 | AN18: =$G18+AL18-AJ18 -> 0 | AO18: 0 | AP18: 0 | AQ18: =ROUND((AO18+AP18)/2,0) -> 0 | AR18: 0 | AU18: =$G18+AS18-AQ18 -> 0 | AV18: =$G18+AT18-AR18 -> 0 | AW18: 0 | AX18: 0 | AY18: =ROUND((AW18+AX18)/2,0) -> 0 | AZ18: 0 | BC18: =$G18+BA18-AY18 -> 0 | BD18: =$G18+BB18-AZ18 -> 0 | BE18: 0 | BF18: 0 | BG18: =ROUND((BE18+BF18)/2,0) -> 0 | BH18: 0 | BK18: =$G18+BI18-BG18 -> 0 | BL18: =$G18+BJ18-BH18 -> 0 | BM18: 0 | BN18: 0 | BO18: =ROUND((BM18+BN18)/2,0) -> 0 | BP18: 0 | BS18: =$G18+BQ18-BO18 -> 0 | BT18: =$G18+BR18-BP18 -> 0 | BU18: 0 | BV18: 0 | BW18: =ROUND((BU18+BV18)/2,0) -> 0 | BX18: 0 | CA18: =$G18+BY18-BW18 -> 0 | CB18: =$G18+BZ18-BX18 -> 0 | CC18: 0 | CD18: 0 | CE18: =ROUND((CC18+CD18)/2,0) -> 0 | CF18: 0 | CI18: =$G18+CG18-CE18 -> 0 | CJ18: =$G18+CH18-CF18 -> 0 | CK18: 0 | CL18: 0 | CM18: =ROUND((CK18+CL18)/2,0) -> 0 | CN18: 0 | CQ18: =$G18+CO18-CM18 -> 0 | CR18: =$G18+CP18-CN18 -> 0 | CS18: 0 | CT18: 0 | CU18: =ROUND((CS18+CT18)/2,0) -> 0 | CV18: 0 | CY18: =$G18+CW18-CU18 -> 0 | CZ18: =$G18+CX18-CV18 -> 0
A19: ABC16 | D19: =_xlfn.XLOOKUP(A19,'ABC-XYZ분석 (2)'!C:C,'ABC-XYZ분석 (2)'!I:I) -> 사계절 | E19: =_xlfn.XLOOKUP(A19,'ABC-XYZ분석 (2)'!C:C,'ABC-XYZ분석 (2)'!AC:AC) -> A | F19: =_xlfn.XLOOKUP(A19,'ABC-XYZ분석 (2)'!C:C,'ABC-XYZ분석 (2)'!AG:AG) -> Y | G19: =SUMIF(재고!C:C,PSI_메인!A19,재고!I:I) -> 24 | H19: 195 | I19: 0 | J19: 0 | K19: 300 | L19: 0 | M19: =SUMIFS(입항스케줄!J:J,입항스케줄!C:C,PSI_메인!A19,입항스케줄!U:U,"2601") -> 0 | N19: =SUMIFS(입항스케줄!J:J,입항스케줄!C:C,PSI_메인!A19,입항스케줄!V:V,"2601") -> 0 | O19: =$G19+M19-K19 -> -276 | P19: =$G19+N19-L19 -> 24 | Q19: 0 | R19: 0 | S19: 75.6 | T19: 0 | U19: =SUMIFS(입항스케줄!J:J,입항스케줄!C:C,PSI_메인!A19,입항스케줄!U:U,"2602") -> 0 | V19: =SUMIFS(입항스케줄!J:J,입항스케줄!C:C,PSI_메인!A19,입항스케줄!V:V,"2602") -> 0 | W19: =$G19+U19-S19 -> -51.6 | X19: =$G19+V19-T19 -> 24 | Y19: 0 | Z19: 0 | AA19: =ROUND((Y19+Z19)/2,0) -> 0 | AB19: 0 | AC19: =SUMIFS(입항스케줄!J:J,입항스케줄!C:C,PSI_메인!A19,입항스케줄!U:U,"2603") -> 0 | AD19: =SUMIFS(입항스케줄!J:J,입항스케줄!C:C,PSI_메인!A19,입항스케줄!V:V,"2603") -> 0 | AE19: =$G19+AC19-AA19 -> 24 | AF19: =$G19+AD19-AB19 -> 24 | AG19: 0 | AH19: 0 | AI19: =ROUND((AG19+AH19)/2,0) -> 0 | AJ19: 0 | AK19: =SUMIFS(입항스케줄!J:J,입항스케줄!C:C,PSI_메인!A19,입항스케줄!U:U,"2604") -> 0 | AL19: =SUMIFS(입항스케줄!J:J,입항스케줄!C:C,PSI_메인!A19,입항스케줄!V:V,"2604") -> 0 | AM19: =$G19+AK19-AI19 -> 24 | AN19: =$G19+AL19-AJ19 -> 24 | AO19: 0 | AP19: 0 | AQ19: =ROUND((AO19+AP19)/2,0) -> 0 | AR19: 0 | AU19: =$G19+AS19-AQ19 -> 24 | AV19: =$G19+AT19-AR19 -> 24 | AW19: 0 | AX19: 0 | AY19: =ROUND((AW19+AX19)/2,0) -> 0 | AZ19: 0 | BC19: =$G19+BA19-AY19 -> 24 | BD19: =$G19+BB19-AZ19 -> 24 | BE19: 0 | BF19: 0 | BG19: =ROUND((BE19+BF19)/2,0) -> 0 | BH19: 0 | BK19: =$G19+BI19-BG19 -> 24 | BL19: =$G19+BJ19-BH19 -> 24 | BM19: 0 | BN19: 0 | BO19: =ROUND((BM19+BN19)/2,0) -> 0 | BP19: 0 | BS19: =$G19+BQ19-BO19 -> 24 | BT19: =$G19+BR19-BP19 -> 24 | BU19: 0 | BV19: 0 | BW19: =ROUND((BU19+BV19)/2,0) -> 0 | BX19: 0 | CA19: =$G19+BY19-BW19 -> 24 | CB19: =$G19+BZ19-BX19 -> 24 | CC19: 0 | CD19: 0 | CE19: =ROUND((CC19+CD19)/2,0) -> 0 | CF19: 0 | CI19: =$G19+CG19-CE19 -> 24 | CJ19: =$G19+CH19-CF19 -> 24 | CK19: 0 | CL19: 0 | CM19: =ROUND((CK19+CL19)/2,0) -> 0 | CN19: 0 | CQ19: =$G19+CO19-CM19 -> 24 | CR19: =$G19+CP19-CN19 -> 24 | CS19: 0 | CT19: 0 | CU19: =ROUND((CS19+CT19)/2,0) -> 0 | CV19: 0 | CY19: =$G19+CW19-CU19 -> 24 | CZ19: =$G19+CX19-CV19 -> 24
A20: ABC17 | D20: =_xlfn.XLOOKUP(A20,'ABC-XYZ분석 (2)'!C:C,'ABC-XYZ분석 (2)'!I:I) -> 사계절 | E20: =_xlfn.XLOOKUP(A20,'ABC-XYZ분석 (2)'!C:C,'ABC-XYZ분석 (2)'!AC:AC) -> A | F20: =_xlfn.XLOOKUP(A20,'ABC-XYZ분석 (2)'!C:C,'ABC-XYZ분석 (2)'!AG:AG) -> Y | G20: =SUMIF(재고!C:C,PSI_메인!A20,재고!I:I) -> 10 | H20: 649 | I20: 0 | J20: 0 | K20: 562.5 | L20: 0 | M20: =SUMIFS(입항스케줄!J:J,입항스케줄!C:C,PSI_메인!A20,입항스케줄!U:U,"2601") -> 0 | N20: =SUMIFS(입항스케줄!J:J,입항스케줄!C:C,PSI_메인!A20,입항스케줄!V:V,"2601") -> 0 | O20: =$G20+M20-K20 -> -552.5 | P20: =$G20+N20-L20 -> 10 | Q20: 0 | R20: 0 | S20: 300 | T20: 0 | U20: =SUMIFS(입항스케줄!J:J,입항스케줄!C:C,PSI_메인!A20,입항스케줄!U:U,"2602") -> 0 | V20: =SUMIFS(입항스케줄!J:J,입항스케줄!C:C,PSI_메인!A20,입항스케줄!V:V,"2602") -> 0 | W20: =$G20+U20-S20 -> -290 | X20: =$G20+V20-T20 -> 10 | Y20: 0 | Z20: 0 | AA20: =ROUND((Y20+Z20)/2,0) -> 0 | AB20: 0 | AC20: =SUMIFS(입항스케줄!J:J,입항스케줄!C:C,PSI_메인!A20,입항스케줄!U:U,"2603") -> 0 | AD20: =SUMIFS(입항스케줄!J:J,입항스케줄!C:C,PSI_메인!A20,입항스케줄!V:V,"2603") -> 0 | AE20: =$G20+AC20-AA20 -> 10 | AF20: =$G20+AD20-AB20 -> 10 | AG20: 0 | AH20: 0 | AI20: =ROUND((AG20+AH20)/2,0) -> 0 | AJ20: 0 | AK20: =SUMIFS(입항스케줄!J:J,입항스케줄!C:C,PSI_메인!A20,입항스케줄!U:U,"2604") -> 0 | AL20: =SUMIFS(입항스케줄!J:J,입항스케줄!C:C,PSI_메인!A20,입항스케줄!V:V,"2604") -> 0 | AM20: =$G20+AK20-AI20 -> 10 | AN20: =$G20+AL20-AJ20 -> 10 | AO20: 0 | AP20: 0 | AQ20: =ROUND((AO20+AP20)/2,0) -> 0 | AR20: 0 | AU20: =$G20+AS20-AQ20 -> 10 | AV20: =$G20+AT20-AR20 -> 10 | AW20: 0 | AX20: 0 | AY20: =ROUND((AW20+AX20)/2,0) -> 0 | AZ20: 0 | BC20: =$G20+BA20-AY20 -> 10 | BD20: =$G20+BB20-AZ20 -> 10 | BE20: 0 | BF20: 0 | BG20: =ROUND((BE20+BF20)/2,0) -> 0 | BH20: 0 | BK20: =$G20+BI20-BG20 -> 10 | BL20: =$G20+BJ20-BH20 -> 10 | BM20: 0 | BN20: 0 | BO20: =ROUND((BM20+BN20)/2,0) -> 0 | BP20: 0 | BS20: =$G20+BQ20-BO20 -> 10 | BT20: =$G20+BR20-BP20 -> 10 | BU20: 0 | BV20: 0 | BW20: =ROUND((BU20+BV20)/2,0) -> 0 | BX20: 0 | CA20: =$G20+BY20-BW20 -> 10 | CB20: =$G20+BZ20-BX20 -> 10 | CC20: 0 | CD20: 0 | CE20: =ROUND((CC20+CD20)/2,0) -> 0 | CF20: 0 | CI20: =$G20+CG20-CE20 -> 10 | CJ20: =$G20+CH20-CF20 -> 10 | CK20: 0 | CL20: 0 | CM20: =ROUND((CK20+CL20)/2,0) -> 0 | CN20: 0 | CQ20: =$G20+CO20-CM20 -> 10 | CR20: =$G20+CP20-CN20 -> 10 | CS20: 0 | CT20: 0 | CU20: =ROUND((CS20+CT20)/2,0) -> 0 | CV20: 0 | CY20: =$G20+CW20-CU20 -> 10 | CZ20: =$G20+CX20-CV20 -> 10
... A102: ABC99 | D102: =_xlfn.XLOOKUP(A102,'ABC-XYZ분석 (2)'!C:C,'ABC-XYZ분석 (2)'!I:I) -> 사계절 | E102: =_xlfn.XLOOKUP(A102,'ABC-XYZ분석 (2)'!C:C,'ABC-XYZ분석 (2)'!AC:AC) -> C | F102: =_xlfn.XLOOKUP(A102,'ABC-XYZ분석 (2)'!C:C,'ABC-XYZ분석 (2)'!AG:AG) -> Y | G102: =SUMIF(재고!C:C,PSI_메인!A102,재고!I:I) -> 500 | H102: 138 | I102: 0 | J102: 0 | K102: 85 | L102: 0 | M102: =SUMIFS(입항스케줄!J:J,입항스케줄!C:C,PSI_메인!A102,입항스케줄!U:U,"2601") -> 0 | N102: =SUMIFS(입항스케줄!J:J,입항스케줄!C:C,PSI_메인!A102,입항스케줄!V:V,"2601") -> 0 | O102: =$G102+M102-K102 -> 415 | P102: =$G102+N102-L102 -> 500 | Q102: 0 | R102: 0 | S102: 59 | T102: 0 | U102: =SUMIFS(입항스케줄!J:J,입항스케줄!C:C,PSI_메인!A102,입항스케줄!U:U,"2602") -> 0 | V102: =SUMIFS(입항스케줄!J:J,입항스케줄!C:C,PSI_메인!A102,입항스케줄!V:V,"2602") -> 0 | W102: =$G102+U102-S102 -> 441 | X102: =$G102+V102-T102 -> 500 | Y102: 0 | Z102: 0 | AA102: =ROUND((Y102+Z102)/2,0) -> 0 | AB102: 0 | AC102: =SUMIFS(입항스케줄!J:J,입항스케줄!C:C,PSI_메인!A102,입항스케줄!U:U,"2603") -> 0 | AD102: =SUMIFS(입항스케줄!J:J,입항스케줄!C:C,PSI_메인!A102,입항스케줄!V:V,"2603") -> 0 | AE102: =$G102+AC102-AA102 -> 500 | AF102: =$G102+AD102-AB102 -> 500 | AG102: 0 | AH102: 0 | AI102: =ROUND((AG102+AH102)/2,0) -> 0 | AJ102: 0 | AK102: =SUMIFS(입항스케줄!J:J,입항스케줄!C:C,PSI_메인!A102,입항스케줄!U:U,"2604") -> 0 | AL102: =SUMIFS(입항스케줄!J:J,입항스케줄!C:C,PSI_메인!A102,입항스케줄!V:V,"2604") -> 0 | AM102: =$G102+AK102-AI102 -> 500 | AN102: =$G102+AL102-AJ102 -> 500 | AO102: 0 | AP102: 0 | AQ102: =ROUND((AO102+AP102)/2,0) -> 0 | AR102: 0 | AU102: =$G102+AS102-AQ102 -> 500 | AV102: =$G102+AT102-AR102 -> 500 | AW102: 0 | AX102: 0 | AY102: =ROUND((AW102+AX102)/2,0) -> 0 | AZ102: 0 | BC102: =$G102+BA102-AY102 -> 500 | BD102: =$G102+BB102-AZ102 -> 500 | BE102: 0 | BF102: 0 | BG102: =ROUND((BE102+BF102)/2,0) -> 0 | BH102: 0 | BK102: =$G102+BI102-BG102 -> 500 | BL102: =$G102+BJ102-BH102 -> 500 | BM102: 0 | BN102: 0 | BO102: =ROUND((BM102+BN102)/2,0) -> 0 | BP102: 0 | BS102: =$G102+BQ102-BO102 -> 500 | BT102: =$G102+BR102-BP102 -> 500 | BU102: 0 | BV102: 0 | BW102: =ROUND((BU102+BV102)/2,0) -> 0 | BX102: 0 | CA102: =$G102+BY102-BW102 -> 500 | CB102: =$G102+BZ102-BX102 -> 500 | CC102: 0 | CD102: 0 | CE102: =ROUND((CC102+CD102)/2,0) -> 0 | CF102: 0 | CI102: =$G102+CG102-CE102 -> 500 | CJ102: =$G102+CH102-CF102 -> 500 | CK102: 0 | CL102: 0 | CM102: =ROUND((CK102+CL102)/2,0) -> 0 | CN102: 0 | CQ102: =$G102+CO102-CM102 -> 500 | CR102: =$G102+CP102-CN102 -> 500 | CS102: 0 | CT102: 0 | CU102: =ROUND((CS102+CT102)/2,0) -> 0 | CV102: 0 | CY102: =$G102+CW102-CU102 -> 500 | CZ102: =$G102+CX102-CV102 -> 500

Sheet 안전재고
A1: SKU 코드 | B1: 제품명 | C1: 리드타임 (일) | D1: 일평균 판매 | E1: 수요 표준편차 | F1: ABC | G1: XYZ | H1: 안전 계수 | I1: 안전재고 | J1: 안전재고 계산식 | M1: 서비스 레벨 | N1: Z-score (안전계수) | O1: 의미 | Q1: XYZ보정계수 (재고 축소목적)
A2: ABC1 | C2: 30 | D2: =30/SUMIF('ABC-XYZ분석 (2)'!C:C,안전재고!A2,'ABC-XYZ분석 (2)'!X:X) -> 5 | E2: =IFERROR('ABC-XYZ분석 (2)'!AE2/30,0) -> 26.102155 | F2: =_xlfn.XLOOKUP(표7[[#This Row],[SKU 코드]],'ABC-XYZ분석 (2)'!C:C,'ABC-XYZ분석 (2)'!AC:AC) -> A | G2: =_xlfn.XLOOKUP(표7[[#This Row],[SKU 코드]],'ABC-XYZ분석 (2)'!C:C,'ABC-XYZ분석 (2)'!AG:AG) -> Z | H2: =_xlfn.XLOOKUP(표7[[#This Row],[ABC]],L:L,N:N) -> 1.48 | I2: =ROUND(E2*SQRT(C2)*표7[[#This Row],[안전 계수]]*_xlfn.XLOOKUP(표7[[#This Row],[XYZ]],Q:Q,R:R),0) -> 212 | J2: 표준편차×√LT×안전계수x보정계수 | L2: C | M2: 0.85 | N2: 1.04 | Q2: X | R2: 0.85
A3: ABC2 | C3: 30 | D3: =30/SUMIF('ABC-XYZ분석 (2)'!C:C,안전재고!A3,'ABC-XYZ분석 (2)'!X:X) -> 4.7368421 | E3: =IFERROR('ABC-XYZ분석 (2)'!AE3/30,0) -> 29.274017 | F3: =_xlfn.XLOOKUP(표7[[#This Row],[SKU 코드]],'ABC-XYZ분석 (2)'!C:C,'ABC-XYZ분석 (2)'!AC:AC) -> A | G3: =_xlfn.XLOOKUP(표7[[#This Row],[SKU 코드]],'ABC-XYZ분석 (2)'!C:C,'ABC-XYZ분석 (2)'!AG:AG) -> Z | H3: =_xlfn.XLOOKUP(표7[[#This Row],[ABC]],L:L,N:N) -> 1.48 | I3: =ROUND(E3*SQRT(C3)*표7[[#This Row],[안전 계수]]*_xlfn.XLOOKUP(표7[[#This Row],[XYZ]],Q:Q,R:R),0) -> 237 | J3: 표준편차×√LT×안전계수x보정계수 | L3: B | M3: 0.9 | N3: 1.28 | O3: 10번 중 1번 품절 | Q3: Y | R3: 1
A4: ABC3 | C4: 30 | D4: =30/SUMIF('ABC-XYZ분석 (2)'!C:C,안전재고!A4,'ABC-XYZ분석 (2)'!X:X) -> 2.6470588 | E4: =IFERROR('ABC-XYZ분석 (2)'!AE4/30,0) -> 31.708022 | F4: =_xlfn.XLOOKUP(표7[[#This Row],[SKU 코드]],'ABC-XYZ분석 (2)'!C:C,'ABC-XYZ분석 (2)'!AC:AC) -> A | G4: =_xlfn.XLOOKUP(표7[[#This Row],[SKU 코드]],'ABC-XYZ분석 (2)'!C:C,'ABC-XYZ분석 (2)'!AG:AG) -> Z | H4: =_xlfn.XLOOKUP(표7[[#This Row],[ABC]],L:L,N:N) -> 1.48 | I4: =ROUND(E4*SQRT(C4)*표7[[#This Row],[안전 계수]]*_xlfn.XLOOKUP(표7[[#This Row],[XYZ]],Q:Q,R:R),0) -> 257 | J4: 표준편차×√LT×안전계수x보정계수 | M4: 0.91 | N4: 1.34 | Q4: Z | R4: 1
A5: ABC4 | C5: 30 | D5: =30/SUMIF('ABC-XYZ분석 (2)'!C:C,안전재고!A5,'ABC-XYZ분석 (2)'!X:X) -> 4.0909091 | E5: =IFERROR('ABC-XYZ분석 (2)'!AE5/30,0) -> 63.898717 | F5: =_xlfn.XLOOKUP(표7[[#This Row],[SKU 코드]],'ABC-XYZ분석 (2)'!C:C,'ABC-XYZ분석 (2)'!AC:AC) -> A | G5: =_xlfn.XLOOKUP(표7[[#This Row],[SKU 코드]],'ABC-XYZ분석 (2)'!C:C,'ABC-XYZ분석 (2)'!AG:AG) -> Z | H5: =_xlfn.XLOOKUP(표7[[#This Row],[ABC]],L:L,N:N) -> 1.48 | I5: =ROUND(E5*SQRT(C5)*표7[[#This Row],[안전 계수]]*_xlfn.XLOOKUP(표7[[#This Row],[XYZ]],Q:Q,R:R),0) -> 518 | J5: 표준편차×√LT×안전계수x보정계수 | M5: 0.92 | N5: 1.41
A6: ABC5 | C6: 30 | D6: =30/SUMIF('ABC-XYZ분석 (2)'!C:C,안전재고!A6,'ABC-XYZ분석 (2)'!X:X) -> 5.625 | E6: =IFERROR('ABC-XYZ분석 (2)'!AE6/30,0) -> 23.037038 | F6: =_xlfn.XLOOKUP(표7[[#This Row],[SKU 코드]],'ABC-XYZ분석 (2)'!C:C,'ABC-XYZ분석 (2)'!AC:AC) -> A | G6: =_xlfn.XLOOKUP(표7[[#This Row],[SKU 코드]],'ABC-XYZ분석 (2)'!C:C,'ABC-XYZ분석 (2)'!AG:AG) -> Z | H6: =_xlfn.XLOOKUP(표7[[#This Row],[ABC]],L:L,N:N) -> 1.48 | I6: =ROUND(E6*SQRT(C6)*표7[[#This Row],[안전 계수]]*_xlfn.XLOOKUP(표7[[#This Row],[XYZ]],Q:Q,R:R),0) -> 187 | J6: 표준편차×√LT×안전계수x보정계수 | L6: A | M6: 0.93 | N6: 1.48
A7: ABC6 | C7: 30 | D7: =30/SUMIF('ABC-XYZ분석 (2)'!C:C,안전재고!A7,'ABC-XYZ분석 (2)'!X:X) -> 6 | E7: =IFERROR('ABC-XYZ분석 (2)'!AE7/30,0) -> 94.120721 | F7: =_xlfn.XLOOKUP(표7[[#This Row],[SKU 코드]],'ABC-XYZ분석 (2)'!C:C,'ABC-XYZ분석 (2)'!AC:AC) -> A | G7: =_xlfn.XLOOKUP(표7[[#This Row],[SKU 코드]],'ABC-XYZ분석 (2)'!C:C,'ABC-XYZ분석 (2)'!AG:AG) -> Z | H7: =_xlfn.XLOOKUP(표7[[#This Row],[ABC]],L:L,N:N) -> 1.48 | I7: =ROUND(E7*SQRT(C7)*표7[[#This Row],[안전 계수]]*_xlfn.XLOOKUP(표7[[#This Row],[XYZ]],Q:Q,R:R),0) -> 763 | J7: 표준편차×√LT×안전계수x보정계수 | M7: 0.94 | N7: 1.55
